Workbook

Sheet EXPIRING ENTERPRISE SOFTWARE
B1: EXPIRATION TIMELINE
B2: <=270 Days | C2: <=180 Days | D2: <=120 Days | E2: <=90 Days | F2: <= 60 Days | G2: <= 30 Days | H2: Expired | J2: Broadcom SiteID: 15750165
A3: SCARS OPE SOFTWARE | B3: =IF(SUM('SCARS OPE'!$J$7:'SCARS OPE'!$J$93)=0,"",SUM('SCARS OPE'!$J$7:'SCARS OPE'!$J$93)/'SCARS OPE'!$S$2) | C3: =IF(SUM('SCARS OPE'!$K$7:'SCARS OPE'!$K$93)=0,"",SUM('SCARS OPE'!$K$7:'SCARS OPE'!$K$93)/'SCARS OPE'!$S$2) -> 1.5 | D3: =IF(SUM('SCARS OPE'!$L$7:'SCARS OPE'!$L$93)=0,"",SUM('SCARS OPE'!$L$7:'SCARS OPE'!$L$93)/'SCARS OPE'!$S$2) | E3: =IF(SUM('SCARS OPE'!$M$7:'SCARS OPE'!$M$93)=0,"",SUM('SCARS OPE'!$M$7:'SCARS OPE'!$M$93)/'SCARS OPE'!$S$2) | F3: =IF(SUM('SCARS OPE'!$N$7:'SCARS OPE'!$N$93)=0,"",SUM('SCARS OPE'!$N$7:'SCARS OPE'!$N$93)/'SCARS OPE'!$S$2) | G3: =IF(SUM('SCARS OPE'!$O$7:'SCARS OPE'!$O$93)=0,"",SUM('SCARS OPE'!$O$7:'SCARS OPE'!$O$93)/'SCARS OPE'!$S$2) -> 3.75 | H3: =IF(SUM('SCARS OPE'!$P$7:'SCARS OPE'!$P$93)=0,"",SUM('SCARS OPE'!$P$7:'SCARS OPE'!$P$93)/'SCARS OPE'!$S$2) -> 0.75 | J3: VMware Contract # 3108150343
A5: JSE OPE SOFTWARE | B5: =IF(SUM('JSE OPE'!$J$7:'JSE OPE'!$J$81)=0,"",SUM('JSE OPE'!$J$7:'JSE OPE'!$J$81)/'JSE OPE'!$S$2) -> 1 | C5: =IF(SUM('JSE OPE'!$K$7:'JSE OPE'!$K$81)=0,"",SUM('JSE OPE'!$K$7:'JSE OPE'!$K$81)/'JSE OPE'!$S$2) -> 0.33333333 | D5: =IF(SUM('JSE OPE'!$L$7:'JSE OPE'!$L$81)=0,"",SUM('JSE OPE'!$L$7:'JSE OPE'!$L$81)/'JSE OPE'!$S$2) | E5: =IF(SUM('JSE OPE'!$M$7:'JSE OPE'!$M$81)=0,"",SUM('JSE OPE'!$M$7:'JSE OPE'!$M$81)/'JSE OPE'!$S$2) | F5: =IF(SUM('JSE OPE'!$N$7:'JSE OPE'!$N$81)=0,"",SUM('JSE OPE'!$N$7:'JSE OPE'!$N$81)/'JSE OPE'!$S$2) | G5: =IF(SUM('JSE OPE'!$O$7:'JSE OPE'!$O$81)=0,"",SUM('JSE OPE'!$O$7:'JSE OPE'!$O$81)/'JSE OPE'!$S$2) -> 2.3333333 | H5: =IF(SUM('JSE OPE'!$P$7:'JSE OPE'!$P$81)=0,"",SUM('JSE OPE'!$P$7:'JSE OPE'!$P$81)/'JSE OPE'!$S$2) -> 0.66666667 | J5: VMware Account# 900295543
A7: DSO PHASE II OPE SOFTWARE | B7: =IF(SUM('DSO PHII OPE'!$J$7:'DSO PHII OPE'!$J$81)=0,"",SUM('DSO PHII OPE'!$J$7:'DSO PHII OPE'!$J$81)/'DSO PHII OPE'!$S$2) -> 6 | C7: =IF(SUM('DSO PHII OPE'!$K$7:'DSO PHII OPE'!$K$81)=0,"",SUM('DSO PHII OPE'!$K$7:'DSO PHII OPE'!$K$81)/'DSO PHII OPE'!$S$2) -> 3 | D7: =IF(SUM('DSO PHII OPE'!$L$7:'DSO PHII OPE'!$L$81)=0,"",SUM('DSO PHII OPE'!$L$7:'DSO PHII OPE'!$L$81)/'DSO PHII OPE'!$S$2) | E7: =IF(SUM('DSO PHII OPE'!$M$7:'DSO PHII OPE'!$M$81)=0,"",SUM('DSO PHII OPE'!$M$7:'DSO PHII OPE'!$M$81)/'DSO PHII OPE'!$S$2) | F7: =IF(SUM('DSO PHII OPE'!$N$7:'DSO PHII OPE'!$N$81)=0,"",SUM('DSO PHII OPE'!$N$7:'DSO PHII OPE'!$N$81)/'DSO PHII OPE'!$S$2) | G7: =IF(SUM('DSO PHII OPE'!$O$7:'DSO PHII OPE'!$O$81)=0,"",SUM('DSO PHII OPE'!$O$7:'DSO PHII OPE'!$O$81)/'DSO PHII OPE'!$S$2) -> 1 | H7: =IF(SUM('DSO PHII OPE'!$P$7:'DSO PHII OPE'!$P$81)=0,"",SUM('DSO PHII OPE'!$P$7:'DSO PHII OPE'!$P$81)/'DSO PHII OPE'!$S$2) -> 1
A9: ARL SCARS LAB OPE SOFTWARE | B9: =IF(SUM('ARL SIL OPE'!$J$7:'ARL SIL OPE'!$J$81)=0,"",SUM('ARL SIL OPE'!$J$7:'ARL SIL OPE'!$J$81)/'ARL SIL OPE'!$S$2) | C9: =IF(SUM('ARL SIL OPE'!$K$7:'ARL SIL OPE'!$K$81)=0,"",SUM('ARL SIL OPE'!$K$7:'ARL SIL OPE'!$K$81)/'ARL SIL OPE'!$S$2) -> 2 | D9: =IF(SUM('ARL SIL OPE'!$L$7:'ARL SIL OPE'!$L$81)=0,"",SUM('ARL SIL OPE'!$L$7:'ARL SIL OPE'!$L$81)/'ARL SIL OPE'!$S$2) | E9: =IF(SUM('ARL SIL OPE'!$M$7:'ARL SIL OPE'!$M$81)=0,"",SUM('ARL SIL OPE'!$M$7:'ARL SIL OPE'!$M$81)/'ARL SIL OPE'!$S$2) -> 1 | F9: =IF(SUM('ARL SIL OPE'!$N$7:'ARL SIL OPE'!$N$81)=0,"",SUM('ARL SIL OPE'!$N$7:'ARL SIL OPE'!$N$81)/'ARL SIL OPE'!$S$2) | G9: =IF(SUM('ARL SIL OPE'!$O$7:'ARL SIL OPE'!$O$81)=0,"",SUM('ARL SIL OPE'!$O$7:'ARL SIL OPE'!$O$81)/'ARL SIL OPE'!$S$2) -> 4 | H9: =IF(SUM('ARL SIL OPE'!$P$7:'ARL SIL OPE'!$P$81)=0,"",SUM('ARL SIL OPE'!$P$7:'ARL SIL OPE'!$P$81)/'ARL SIL OPE'!$S$2) -> 1
A11: SCARS uSOC SOFTWARE | B11: =IF(SUM('SCARS uSOC'!$J$7:'SCARS uSOC'!$J$84)=0,"",SUM('SCARS uSOC'!$J$7:'SCARS uSOC'!$J$84)/'SCARS uSOC'!$S$2) -> 1 | C11: =IF(SUM('SCARS uSOC'!$K$7:'SCARS uSOC'!$K$84)=0,"",SUM('SCARS uSOC'!$K$7:$K$84)/'SCARS uSOC'!$S$2) -> 2 | D11: =IF(SUM('SCARS uSOC'!$L$7:'SCARS uSOC'!$L$84)=0,"",SUM('SCARS uSOC'!$L$7:'SCARS uSOC'!$L$84)/'SCARS uSOC'!$S$2) -> 1 | E11: =IF(SUM('SCARS uSOC'!$M$7:'SCARS uSOC'!$M$84)=0,"",SUM('SCARS uSOC'!$M$7:'SCARS uSOC'!$M$84)/'SCARS uSOC'!$S$2) | F11: =IF(SUM('SCARS uSOC'!$N$7:'SCARS uSOC'!$N$84)=0,"",SUM('SCARS uSOC'!$N$7:'SCARS uSOC'!$N$84)/'SCARS uSOC'!$S$2) | G11: =IF(SUM('SCARS uSOC'!$O$7:'SCARS uSOC'!$O$84)=0,"",SUM('SCARS uSOC'!$O$7:'SCARS uSOC'!$O$84)/'SCARS uSOC'!$S$2) -> 7 | H11: =IF(SUM('SCARS uSOC'!$P$7:'SCARS uSOC'!$P$84)=0,"",SUM('SCARS uSOC'!$P$7:'SCARS uSOC'!$P$84)/'SCARS uSOC'!$S$2) -> 2
A13: SCARS sSOC SOFTWARE | B13: =IF(SUM('SCARS sSOC'!$J$7:'SCARS sSOC'!$J$85)=0,"",SUM('SCARS sSOC'!$J$7:'SCARS sSOC'!$J$85)/'SCARS sSOC'!$S$2) -> 1 | C13: =IF(SUM('SCARS sSOC'!$K$7:'SCARS sSOC'!$K$85)=0,"",SUM('SCARS sSOC'!$K$7:'SCARS sSOC'!$K$85)/'SCARS sSOC'!$S$2) -> 2 | D13: =IF(SUM('SCARS sSOC'!$L$7:'SCARS sSOC'!$L$85)=0,"",SUM('SCARS sSOC'!$L$7:'SCARS sSOC'!$L$85)/'SCARS sSOC'!$S$2) | E13: =IF(SUM('SCARS sSOC'!$M$7:'SCARS sSOC'!$M$85)=0,"",SUM('SCARS sSOC'!$M$7:'SCARS sSOC'!$M$85)/'SCARS sSOC'!$S$2) | F13: =IF(SUM('SCARS sSOC'!$N$7:'SCARS sSOC'!$N$85)=0,"",SUM('SCARS sSOC'!$N$7:'SCARS sSOC'!$N$85)/'SCARS sSOC'!$S$2) -> 1 | G13: =IF(SUM('SCARS sSOC'!$O$7:'SCARS sSOC'!$O$85)=0,"",SUM('SCARS sSOC'!$O$7:'SCARS sSOC'!$O$85)/'SCARS sSOC'!$S$2) -> 7 | H13: =IF(SUM('SCARS sSOC'!$P$7:'SCARS sSOC'!$P$85)=0,"",SUM('SCARS sSOC'!$P$7:'SCARS sSOC'!$P$85)/'SCARS sSOC'!$S$2) -> 3
A15: ARL SCARS LAB SOC SOFTWARE | B15: =IF(SUM('ARL SIL SOC'!$J$7:'ARL SIL SOC'!$J$81)=0,"",SUM('ARL SIL SOC'!$J$7:'ARL SIL SOC'!$J$81)/'ARL SIL SOC'!$S$2) | C15: =IF(SUM('ARL SIL SOC'!$K$7:'ARL SIL SOC'!$K$81)=0,"",SUM('ARL SIL SOC'!$K$7:'ARL SIL SOC'!$K$81)/'ARL SIL SOC'!$S$2) -> 2 | D15: =IF(SUM('ARL SIL SOC'!$L$7:'ARL SIL SOC'!$L$81)=0,"",SUM('ARL SIL SOC'!$L$7:'ARL SIL SOC'!$L$81)/'ARL SIL SOC'!$S$2) | E15: =IF(SUM('ARL SIL SOC'!$M$7:'ARL SIL SOC'!$M$81)=0,"",SUM('ARL SIL SOC'!$M$7:'ARL SIL SOC'!$M$81)/'ARL SIL SOC'!$S$2) | F15: =IF(SUM('ARL SIL SOC'!$N$7:'ARL SIL SOC'!$N$81)=0,"",SUM('ARL SIL SOC'!$N$7:'ARL SIL SOC'!$N$81)/'ARL SIL SOC'!$S$2) | G15: =IF(SUM('ARL SIL SOC'!$O$7:'ARL SIL SOC'!$O$81)=0,"",SUM('ARL SIL SOC'!$O$7:'ARL SIL SOC'!$O$81)/'ARL SIL SOC'!$S$2) -> 6 | H15: =IF(SUM('ORL SIL SOC'!$P$7:'ORL SIL SOC'!$P$81)=0,"",SUM('ORL SIL SOC'!$P$7:'ORL SIL SOC'!$P$81)/'ORL SIL SOC'!$S$2) -> 1
A17: GDR | B17: =IF(SUM(GDR!$J$7:'GDR'!$J$81)=0,"",SUM(GDR!$J$7:'GDR'!$J$81)/GDR!$S$2) | C17: =IF(SUM(GDR!$K$7:'GDR'!$K$81)=0,"",SUM(GDR!$K$7:'GDR'!$K$81)/GDR!$S$2) | D17: =IF(SUM(GDR!$L$7:'GDR'!$L$81)=0,"",SUM(GDR!$L$7:'GDR'!$L$81)/GDR!$S$2) | E17: =IF(SUM(GDR!$M$7:'GDR'!$M$81)=0,"",SUM(GDR!$M$7:'GDR'!$M$81)/GDR!$S$2) | F17: =IF(SUM(GDR!$N$7:'GDR'!$N$81)=0,"",SUM(GDR!$N$7:'GDR'!$N$81)/GDR!$S$2) | G17: =IF(SUM(GDR!$O$7:'GDR'!$O$81)=0,"",SUM(GDR!$O$7:'GDR'!$O$81)/GDR!$S$2) | H17: =IF(SUM(GDR!$P$7:'GDR'!$P$81)=0,"",SUM(GDR!$P$7:'GDR'!$P$81)/GDR!$S$2)
A19: ORL SIL SOC | B19: =IF(SUM('ORL SIL SOC'!$J$7:'ORL SIL SOC'!$J$81)=0,"",SUM('ORL SIL SOC'!$J$7:'ORL SIL SOC'!$J$81)/'ORL SIL SOC'!$S$2) | C19: =IF(SUM('ORL SIL SOC'!$K$7:'ORL SIL SOC'!$K$81)=0,"",SUM('ORL SIL SOC'!$K$7:'ORL SIL SOC'!$K$81)/'ORL SIL SOC'!$S$2) -> 2 | D19: =IF(SUM('ORL SIL SOC'!$L$7:'ORL SIL SOC'!$L$81)=0,"",SUM('ORL SIL SOC'!$L$7:'ORL SIL SOC'!$L$81)/'ORL SIL SOC'!$S$2) -> 1 | E19: =IF(SUM('ORL SIL SOC'!$M$7:'ORL SIL SOC'!$M$81)=0,"",SUM('ORL SIL SOC'!$M$7:'ORL SIL SOC'!$M$81)/'ORL SIL SOC'!$S$2) -> 2 | F19: =IF(SUM('ORL SIL SOC'!$N$7:'ORL SIL SOC'!$N$81)=0,"",SUM('ORL SIL SOC'!$N$7:'ORL SIL SOC'!$N$81)/'ORL SIL SOC'!$S$2) | G19: =IF(SUM('ORL SIL SOC'!$O$7:'ORL SIL SOC'!$O$81)=0,"",SUM('ORL SIL SOC'!$O$7:'ORL SIL SOC'!$O$81)/'ORL SIL SOC'!$S$2) -> 4 | H19: =IF(SUM('ORL SIL SOC'!$P$7:'ORL SIL SOC'!$P$81)=0,"",SUM('ORL SIL SOC'!$P$7:'ORL SIL SOC'!$P$81)/'ORL SIL SOC'!$S$2) -> 1
A21: SiSOC | B21: =IF(SUM(SiSOC!$I$7:'SiSOC'!$I$81)=0,"",SUM(SiSOC!$I$7:'SiSOC'!$I$81)/SiSOC!$S$2) -> 16 | C21: =IF(SUM(SiSOC!$J$7:'SiSOC'!$J$81)=0,"",SUM(SiSOC!$J$7:'SiSOC'!$J$81)/SiSOC!$R$2) | D21: =IF(SUM(SiSOC!$K$7:'SiSOC'!$K$81)=0,"",SUM(SiSOC!$K$7:'SiSOC'!$K$81)/SiSOC!$R$2) | E21: =IF(SUM(SiSOC!$L$7:'SiSOC'!$L$81)=0,"",SUM(SiSOC!$L$7:'SiSOC'!$L$81)/SiSOC!$R$2) | F21: =IF(SUM(SiSOC!$M$7:'SiSOC'!$M$81)=0,"",SUM(SiSOC!$M$7:'SiSOC'!$M$81)/SiSOC!$R$2) | G21: =IF(SUM(SiSOC!$N$7:'SiSOC'!$N$81)=0,"",SUM(SiSOC!$N$7:'SiSOC'!$N$81)/SiSOC!$R$2) | H21: =IF(SUM(SiSOC!$O$7:'SiSOC'!$O$81)=0,"",SUM(SiSOC!$O$7:'SiSOC'!$O$81)/SiSOC!$R$2)
A23: V4 OPE | B23: =IF(SUM('V4 OPE'!$I$7:'V4 OPE'!$I$81)=0,"",SUM('V4 OPE'!$I$7:'V4 OPE'!$I$81)/'V4 OPE'!$S$2) -> 16 | C23: =IF(SUM('V4 OPE'!$J$7:'V4 OPE'!$J$81)=0,"",SUM('V4 OPE'!$J$7:'V4 OPE'!$J$81)/'V4 OPE'!$R$2) | D23: =IF(SUM('V4 OPE'!$K$7:'V4 OPE'!$K$81)=0,"",SUM('V4 OPE'!$K$7:'V4 OPE'!$K$81)/'V4 OPE'!$R$2) | E23: =IF(SUM('V4 OPE'!$L$7:'V4 OPE'!$L$81)=0,"",SUM('V4 OPE'!$L$7:'V4 OPE'!$L$81)/'V4 OPE'!$R$2) | F23: =IF(SUM('V4 OPE'!$M$7:'V4 OPE'!$M$81)=0,"",SUM('V4 OPE'!$M$7:'V4 OPE'!$M$81)/'V4 OPE'!$R$2) | G23: =IF(SUM('V4 OPE'!$N$7:'V4 OPE'!$N$81)=0,"",SUM('V4 OPE'!$N$7:'V4 OPE'!$N$81)/'V4 OPE'!$R$2) | H23: =IF(SUM('V4 OPE'!$O$7:'V4 OPE'!$O$81)=0,"",SUM('V4 OPE'!$O$7:'V4 OPE'!$O$81)/'V4 OPE'!$R$2)
A26: ASSUMPTIONS:
A27: 1. With no access to devices reference made to "potentially outdated" software tracking Excel Spreadsheet (https://azucaeusa.sharepoint.us/:x:/r/sites/SCARSPrime/Shared%20Documents/General/26_SCARS%20Software/SCARS%20SW%20Master%20Tracking%20sheet%2012_22.xlsx?d=wc5d20e0ee1ae4926850f5944f4899752&csf=1&web=1&e=Rmv05K)
A28: 2. The expiration dates on the above referenced spreadsheet were used as a basis for assuming "current" expiration dates
A29: 3. Not all software has been identified, knowledgeable individuals can update the appropriate tabs
A30: 4. The chart above is updated "automatically." Individuals can proceed to the appropriate tabs to see the specific "expiring" software
A31: 5. SCARS OPEs have the same software expiration dates
A32: 6. End of Life (EOL) reference https://endoflife.date

Sheet SCARS sSOC
B1: How to use: | G1: Ensure the license duration (column F) is correct. Update the software activation / installation date for each device. Expiration date will be computed based on license duration. | BF1: sSOC
I2: Expiration Timeframe | Q2: =TODAY() -> 45931 | S2: =COUNTA(BF1:FU1) -> 1 | BF2: Orlando | BI2: Future | BL2: Future | BO2: Future | BR2: Future | BU2: Future | BX2: Future | CA2: Future | CD2: Future | CG2: Future | CJ2: Future | CM2: Future | CP2: Future | CS2: Future | CV2: Future | CY2: Future | DB2: Future | DE2: Future | DH2: Future | DK2: Future | DN2: Future | DQ2: Future | DT2: Future | DW2: Future | DZ2: Future | EC2: Future | EF2: Future | EI2: Future | EL2: Future | EO2: Future | ER2: Future | EU2: Future | EX2: Future | FA2: Future | FD2: Future | FG2: Future | FJ2: Future | FM2: Future | FP2: Future | FS2: Future | FV2: Remarks
G3: SCN:
G4: Task Order Number:
G5: Project Number:
A6: License Renewals Required | B6: Part Number | C6: Unit Cost | D6: Total Cost | E6: License Quantities Per Unit | F6: End of Life (EOL) Dates | G6: License Duration (in Years) | H6: Software Description | I6: >270 Days | J6: <=270 Days | K6: <=180 Days | L6: <=120 Days | M6: <=90 Days | N6: <= 60 Days | O6: <= 30 Days | P6: Expired | BF6: Software Activation / Install Date | BH6: License Expiration Date | BI6: Software Activation / Install Date | BK6: License Expiration Date | BL6: Software Activation / Install Date | BN6: License Expiration Date | BO6: Software Activation / Install Date | BQ6: License Expiration Date | BR6: Software Activation / Install Date | BT6: License Expiration Date | BU6: Software Activation / Install Date | BW6: License Expiration Date | BX6: Software Activation / Install Date | BZ6: License Expiration Date | CA6: Software Activation / Install Date | CC6: License Expiration Date | CD6: Software Activation / Install Date | CF6: License Expiration Date | CG6: Software Activation / Install Date | CI6: License Expiration Date | CJ6: Software Activation / Install Date | CL6: License Expiration Date | CM6: Software Activation / Install Date | CO6: License Expiration Date | CP6: Software Activation / Install Date | CR6: License Expiration Date | CS6: Software Activation / Install Date | CU6: License Expiration Date | CV6: Software Activation / Install Date | CX6: License Renewal Date | CY6: Software Activation / Install Date | DA6: License Expiration Date | DB6: Software Activation / Install Date | DD6: License Renewal Date | DE6: Software Activation / Install Date | DG6: License Expiration Date | DH6: Software Activation / Install Date | DJ6: License Renewal Date | DK6: Software Activation / Install Date | DM6: License Expiration Date | DN6: Software Activation / Install Date | DP6: License Renewal Date | DQ6: Software Activation / Install Date | DS6: License Expiration Date | DT6: Software Activation / Install Date | DV6: License Renewal Date | DW6: Software Activation / Install Date | DY6: License Expiration Date | DZ6: Software Activation / Install Date | EB6: License Renewal Date | EC6: Software Activation / Install Date | EE6: License Expiration Date | EF6: Software Activation / Install Date | EH6: License Renewal Date | EI6: Software Activation / Install Date | EK6: License Expiration Date | EL6: Software Activation / Install Date | EN6: License Renewal Date | EO6: Software Activation / Install Date | EQ6: License Expiration Date | ER6: Software Activation / Install Date | ET6: License Renewal Date | EU6: Software Activation / Install Date | EW6: License Expiration Date | EX6: Software Activation / Install Date | EZ6: License Renewal Date | FA6: Software Activation / Install Date | FC6: License Expiration Date | FD6: Software Activation / Install Date | FF6: License Renewal Date | FG6: Software Activation / Install Date | FI6: License Expiration Date | FJ6: Software Activation / Install Date | FL6: License Renewal Date | FM6: Software Activation / Install Date | FO6: License Expiration Date | FP6: Software Activation / Install Date | FR6: License Renewal Date | FS6: Software Activation / Install Date | FU6: License Expiration Date | GA6: Number of Devices:
A7: =IF(E7="","",E7*$GA$7) -> 128 | B7: P007189-008 | C7: 79.99 | D7: =IF(A7="","",A7*C7) -> 10238.72 | E7: 128 | F7: 2016 - 1/12/27 2019 - 1/9/29 2022 - 10/14/31 23H2 - 10/24/25 | G7: N/A | H7: WinSvrSTDCore ALNG LicSAPk MVL 2Lic CoreLic | I7: =IF(COUNTIFS($Q7:$BD7,">270")=0,"",COUNTIFS($Q7:$BD7,">270")) | J7: =IF(COUNTIFS($Q7:$BD7,"<=270")>0,IF(COUNTIFS($Q7:$BD7,"<=270")-COUNTIFS($Q7:$BD7,"<=180")=0,"",COUNTIFS($Q7:$BD7,"<=270")-COUNTIFS($Q7:$BD7,"<=180")),"") | K7: =IF(COUNTIFS($Q7:$BD7,"<=180")>0,IF(COUNTIFS($Q7:$BD7,"<=180")-COUNTIFS($Q7:$BD7,"<=120")=0,"",COUNTIFS($Q7:$BD7,"<=180")-COUNTIFS($Q7:$BD7,"<=120")),"") | L7: =IF(COUNTIFS($Q7:$BD7,"<=120")>0,IF(COUNTIFS($Q7:$BD7,"<=120")-COUNTIFS($Q7:$BD7,"<=90")=0,"",COUNTIFS($Q7:$BD7,"<=120")-COUNTIFS($Q7:$BD7,"<=90")),"") | M7: =IF(COUNTIFS($Q7:$BD7,"<=90")>0,IF(COUNTIFS($Q7:$BD7,"<=90")-COUNTIFS($Q7:$BD7,"<=60")=0,"",COUNTIFS($Q7:$BD7,"<=90")-COUNTIFS($Q7:$BD7,"<=60")),"") | N7: =IF(COUNTIFS($Q7:$BD7,"<=60")>0,IF(COUNTIFS($Q7:$BD7,"<=60")-COUNTIFS($Q7:$BD7,"<=30")=0,"",COUNTIFS($Q7:$BD7,"<=60")-COUNTIFS($Q7:$BD7,"<=30")),"") | O7: =IF(COUNTIFS($Q7:$BD7,"<=30")>0,IF(COUNTIFS($Q7:$BD7,"<=30")-COUNTIFS($Q7:$BD7,"<=0")=0,"",COUNTIFS($Q7:$BD7,"<=30")-COUNTIFS($Q7:$BD7,"<=0")),"") | P7: =IF(COUNTIFS($Q7:$BD7,"<=0")=0,"",COUNTIFS($Q7:$BD7,"<=0")) | Q7: =IF($S$2>0,IF(BG7="","",BG7),"") -> #VALUE! | R7: =IF($S$2>1,IF(BJ7="","",BJ7),"") | S7: =IF($S$2>2,IF(BM7="","",BM7),"") | T7: =IF($S$2>3,IF(BP7="","",BP7),"") | U7: =IF($S$2>4,IF(BS7="","",BS7),"") | V7: =IF($S$2>5,IF(BV7="","",BV7),"") | W7: =IF($S$2>6,IF(BY7="","",BY7),"") | X7: =IF($S$2>7,IF(CB7="","",CB7),"") | Y7: =IF($S$2>8,IF(CE7="","",CE7),"") | Z7: =IF($S$2>9,IF(CH7="","",CH7),"") | AA7: =IF($S$2>10,IF(CK7="","",CK7),"") | AB7: =IF($S$2>11,IF(CN7="","",CN7),"") | AC7: =IF($S$2>12,IF(CQ7="","",CQ7),"") | AD7: =IF($S$2>13,IF(CT7="","",CT7),"") | AE7: =IF($S$2>14,IF(CW7="","",CW7),"") | AF7: =IF($S$2>15,IF(CZ7="","",CZ7),"") | AG7: =IF($S$2>16,IF(DC7="","",DC7),"") | AH7: =IF($S$2>17,IF(DF7="","",DF7),"") | AI7: =IF($S$2>18,IF(DI7 = "","",DI7),"") | AJ7: =IF($S$2>19,IF(DL7="","",DL7),"") | AK7: =IF($S$2>20,IF(DO7="","",DO7),"") | AL7: =IF($S$2>21,IF(DR7="","",DR7),"") | AM7: =IF($S$2>22,IF(DU7="","",DU7),"") | AN7: =IF($S$2>23,IF(DX7="","",DX7),"") | AO7: =IF($S$2>24,IF(EA7="","",EA7),"") | AP7: =IF($S$2>25,IF(ED7="","",ED7),"") | AQ7: =IF($S$2>26,IF(EG7="","",EG7),"") | AR7: =IF($S$2>27,IF(EJ7="","",EJ7),"") | AS7: =IF($S$2>28,IF(EM7="","",EM7),"") | AT7: =IF($S$2>29,IF(EP7 = "", "", EP7),"") | AU7: =IF($S$2>30,IF(ES7="","",ES7),"") | AV7: =IF($S$2>31,IF(EV7="","",EV7),"") | AW7: =IF($S$2>32,IF(EY7="","",EY7),"") | AX7: =IF($S$2>33,IF(FB7="","",FB7),"") | AY7: =IF($S$2>34,IF(FE7="","",FE7),"") | AZ7: =IF($S$2>35,IF(FH7="","",FH7),"") | BA7: =IF($S$2>36,IF(FK7="","",FK7),"") | BB7: =IF($S$2>37,IF(FN7="","",FN7),"") | BC7: =IF($S$2>38,IF(FQ7="","",FQ7),"") | BD7: =IF($S$2>39,IF(FT7="","",FT7),"") | BE7: =IF($S$2>40,IF(FW7="","",FW7),"") | BF7: 45337 | BG7: =IF(BH7="","",_xlfn.DAYS(BH7,$Q$2)) -> #VALUE! | BH7: =IF(BF7="","",BF7+($G7*365)) -> #VALUE! | BJ7: =IF(BK7="","",_xlfn.DAYS(BK7,$Q$2)) | BK7: =IF(BI7="","",BI7+($G7*365)) | BM7: =IF(BN7="","",_xlfn.DAYS(BN7,$Q$2)) | BN7: =IF(BL7="","",BL7+($G7*365)) | BP7: =IF(BQ7="","",_xlfn.DAYS(BQ7,$Q$2)) | BQ7: =IF(BO7="","",BO7+($G7*365)) | BS7: =IF(BT7="","",_xlfn.DAYS(BT7,$Q$2)) | BT7: =IF(BR7="","",BR7+($G7*365)) | BV7: =IF(BW7="","",_xlfn.DAYS(BW7,$Q$2)) | BW7: =IF(BU7="","",BU7+($G7*365)) | BY7: =IF(BZ7="","",_xlfn.DAYS(BZ7,$Q$2)) | BZ7: =IF(BX7="","",BX7+($G7*365)) | CB7: =IF(CC7="","",_xlfn.DAYS(CC7,$Q$2)) | CC7: =IF(CA7="","",CA7+($G7*365)) | CE7: =IF(CF7="","",_xlfn.DAYS(CF7,$Q$2)) | CF7: =IF(CD7="","",CD7+($G7*365)) | CH7: =IF(CI7="","",_xlfn.DAYS(CI7,$Q$2)) | CI7: =IF(CG7="","",CG7+($G7*365)) | CK7: =IF(CL7="","",_xlfn.DAYS(CL7,$Q$2)) | CL7: =IF(CJ7="","",CJ7+($G7*365)) | CN7: =IF(CO7="","",_xlfn.DAYS(CO7,$Q$2)) | CO7: =IF(CM7="","",CM7+($G7*365)) | CQ7: =IF(CR7="","",_xlfn.DAYS(CR7,$Q$2)) | CR7: =IF(CP7="","",CP7+($G7*365)) | CT7: =IF(CU7="","",_xlfn.DAYS(CU7,$Q$2)) | CU7: =IF(CS7="","",CS7+($G7*365)) | CW7: =IF(CX7="","",_xlfn.DAYS(CX7,$Q$2)) | CX7: =IF(CV7="","",CV7+($G7*365)) | CZ7: =IF(DA7="","",_xlfn.DAYS(DA7,$Q$2)) | DA7: =IF(CY7="","",CY7+($G7*365)) | DC7: =IF(DD7="","",_xlfn.DAYS(DD7,$Q$2)) | DD7: =IF(DB7="","",DB7+($G7*365)) | DF7: =IF(DG7="","",_xlfn.DAYS(DG7,$Q$2)) | DG7: =IF(DE7="","",DE7+($G7*365)) | DI7: =IF(DJ7="","",_xlfn.DAYS(DJ7,$Q$2)) | DJ7: =IF(DH7="","",DH7+($G7*365)) | DL7: =IF(DM7="","",_xlfn.DAYS(DM7,$Q$2)) | DM7: =IF(DK7="","",DK7+($G7*365)) | DO7: =IF(DP7="","",_xlfn.DAYS(DP7,$Q$2)) | DP7: =IF(DN7="","",DN7+($G7*365)) | DR7: =IF(DS7="","",_xlfn.DAYS(DS7,$Q$2)) | DS7: =IF(DQ7="","",DQ7+($G7*365)) | DU7: =IF(DV7="","",_xlfn.DAYS(DV7,$Q$2)) | DV7: =IF(DT7="","",DT7+($G7*365)) | DX7: =IF(DY7="","",_xlfn.DAYS(DY7,$Q$2)) | DY7: =IF(DW7="","",DW7+($G7*365)) | EA7: =IF(EB7="","",_xlfn.DAYS(EB7,$Q$2)) | EB7: =IF(DZ7="","",DZ7+($G7*365)) | ED7: =IF(EE7="","",_xlfn.DAYS(EE7,$Q$2)) | EE7: =IF(EC7="","",EC7+($G7*365)) | EG7: =IF(EH7="","",_xlfn.DAYS(EH7,$Q$2)) | EH7: =IF(EF7="","",EF7+($G7*365)) | EJ7: =IF(EK7="","",_xlfn.DAYS(EK7,$Q$2)) | EK7: =IF(EI7="","",EI7+($G7*365)) | EM7: =IF(EN7="","",_xlfn.DAYS(EN7,$Q$2)) | EN7: =IF(EL7="","",EL7+($G7*365)) | EP7: =IF(EQ7="","",_xlfn.DAYS(EQ7,$Q$2)) | EQ7: =IF(EO7="","",EO7+($G7*365)) | ES7: =IF(ET7="","",_xlfn.DAYS(ET7,$Q$2)) | ET7: =IF(ER7="","",ER7+($G7*365)) | EV7: =IF(EW7="","",_xlfn.DAYS(EW7,$Q$2)) | EW7: =IF(EU7="","",EU7+($G7*365)) | EY7: =IF(EZ7="","",_xlfn.DAYS(EZ7,$Q$2)) | EZ7: =IF(EX7="","",EX7+($G7*365)) | FB7: =IF(FC7="","",_xlfn.DAYS(FC7,$Q$2)) | FC7: =IF(FA7="","",FA7+($G7*365)) | FE7: =IF(FF7="","",_xlfn.DAYS(FF7,$Q$2)) | FF7: =IF(FD7="","",FD7+($G7*365)) | FH7: =IF(FI7="","",_xlfn.DAYS(FI7,$Q$2)) | FI7: =IF(FG7="","",FG7+($G7*365)) | FK7: =IF(FL7="","",_xlfn.DAYS(FL7,$Q$2)) | FL7: =IF(FJ7="","",FJ7+($G7*365)) | FN7: =IF(FO7="","",_xlfn.DAYS(FO7,$Q$2)) | FO7: =IF(FM7="","",FM7+($G7*365)) | FQ7: =IF(FR7="","",_xlfn.DAYS(FR7,$Q$2)) | FR7: =IF(FP7 = "", "",FP7+($G7*365)) | FT7: =IF(FU7="","",_xlfn.DAYS(FU7,$Q$2)) | FU7: =IF(FS7="","",FS7+($G7*365)) | GA7: =$S$2 -> 1
A8: =IF(E8="","",E8*$GA$7) -> 12 | B8: P004173-030 | C8: 0 | D8: =IF(A8="","",A8*C8) -> 0 | E8: 12 | G8: N/A | H8: CoreCAL ALNG LicSAPk MVL Pltfrm UsrCAL | I8: =IF(COUNTIFS($Q8:$BD8,">270")=0,"",COUNTIFS($Q8:$BD8,">270")) | J8: =IF(COUNTIFS($Q8:$BD8,"<=270")>0,IF(COUNTIFS($Q8:$BD8,"<=270")-COUNTIFS($Q8:$BD8,"<=180")=0,"",COUNTIFS($Q8:$BD8,"<=270")-COUNTIFS($Q8:$BD8,"<=180")),"") | K8: =IF(COUNTIFS($Q8:$BD8,"<=180")>0,IF(COUNTIFS($Q8:$BD8,"<=180")-COUNTIFS($Q8:$BD8,"<=120")=0,"",COUNTIFS($Q8:$BD8,"<=180")-COUNTIFS($Q8:$BD8,"<=120")),"") | L8: =IF(COUNTIFS($Q8:$BD8,"<=120")>0,IF(COUNTIFS($Q8:$BD8,"<=120")-COUNTIFS($Q8:$BD8,"<=90")=0,"",COUNTIFS($Q8:$BD8,"<=120")-COUNTIFS($Q8:$BD8,"<=90")),"") | M8: =IF(COUNTIFS($Q8:$BD8,"<=90")>0,IF(COUNTIFS($Q8:$BD8,"<=90")-COUNTIFS($Q8:$BD8,"<=60")=0,"",COUNTIFS($Q8:$BD8,"<=90")-COUNTIFS($Q8:$BD8,"<=60")),"") | N8: =IF(COUNTIFS($Q8:$BD8,"<=60")>0,IF(COUNTIFS($Q8:$BD8,"<=60")-COUNTIFS($Q8:$BD8,"<=30")=0,"",COUNTIFS($Q8:$BD8,"<=60")-COUNTIFS($Q8:$BD8,"<=30")),"") | O8: =IF(COUNTIFS($Q8:$BD8,"<=30")>0,IF(COUNTIFS($Q8:$BD8,"<=30")-COUNTIFS($Q8:$BD8,"<=0")=0,"",COUNTIFS($Q8:$BD8,"<=30")-COUNTIFS($Q8:$BD8,"<=0")),"") | P8: =IF(COUNTIFS($Q8:$BD8,"<=0")=0,"",COUNTIFS($Q8:$BD8,"<=0")) | Q8: =IF($S$2>0,IF(BG8="","",BG8),"") -> #VALUE! | R8: =IF($S$2>1,IF(BJ8="","",BJ8),"") | S8: =IF($S$2>2,IF(BM8="","",BM8),"") | T8: =IF($S$2>3,IF(BP8="","",BP8),"") | U8: =IF($S$2>4,IF(BS8="","",BS8),"") | V8: =IF($S$2>5,IF(BV8="","",BV8),"") | W8: =IF($S$2>6,IF(BY8="","",BY8),"") | X8: =IF($S$2>7,IF(CB8="","",CB8),"") | Y8: =IF($S$2>8,IF(CE8="","",CE8),"") | Z8: =IF($S$2>9,IF(CH8="","",CH8),"") | AA8: =IF($S$2>10,IF(CK8="","",CK8),"") | AB8: =IF($S$2>11,IF(CN8="","",CN8),"") | AC8: =IF($S$2>12,IF(CQ8="","",CQ8),"") | AD8: =IF($S$2>13,IF(CT8="","",CT8),"") | AE8: =IF($S$2>14,IF(CW8="","",CW8),"") | AF8: =IF($S$2>15,IF(CZ8="","",CZ8),"") | AG8: =IF($S$2>16,IF(DC8="","",DC8),"") | AH8: =IF($S$2>17,IF(DF8="","",DF8),"") | AI8: =IF($S$2>18,IF(DI8 = "","",DI8),"") | AJ8: =IF($S$2>19,IF(DL8="","",DL8),"") | AK8: =IF($S$2>20,IF(DO8="","",DO8),"") | AL8: =IF($S$2>21,IF(DR8="","",DR8),"") | AM8: =IF($S$2>22,IF(DU8="","",DU8),"") | AN8: =IF($S$2>23,IF(DX8="","",DX8),"") | AO8: =IF($S$2>24,IF(EA8="","",EA8),"") | AP8: =IF($S$2>25,IF(ED8="","",ED8),"") | AQ8: =IF($S$2>26,IF(EG8="","",EG8),"") | AR8: =IF($S$2>27,IF(EJ8="","",EJ8),"") | AS8: =IF($S$2>28,IF(EM8="","",EM8),"") | AT8: =IF($S$2>29,IF(EP8 = "", "", EP8),"") | AU8: =IF($S$2>30,IF(ES8="","",ES8),"") | AV8: =IF($S$2>31,IF(EV8="","",EV8),"") | AW8: =IF($S$2>32,IF(EY8="","",EY8),"") | AX8: =IF($S$2>33,IF(FB8="","",FB8),"") | AY8: =IF($S$2>34,IF(FE8="","",FE8),"") | AZ8: =IF($S$2>35,IF(FH8="","",FH8),"") | BA8: =IF($S$2>36,IF(FK8="","",FK8),"") | BB8: =IF($S$2>37,IF(FN8="","",FN8),"") | BC8: =IF($S$2>38,IF(FQ8="","",FQ8),"") | BD8: =IF($S$2>39,IF(FT8="","",FT8),"") | BE8: =IF($S$2>40,IF(FW8="","",FW8),"") | BF8: 45337 | BG8: =IF(BH8="","",_xlfn.DAYS(BH8,$Q$2)) -> #VALUE! | BH8: =IF(BF8="","",BF8+($G8*365)) -> #VALUE! | BJ8: =IF(BK8="","",_xlfn.DAYS(BK8,$Q$2)) | BK8: =IF(BI8="","",BI8+($G8*365)) | BM8: =IF(BN8="","",_xlfn.DAYS(BN8,$Q$2)) | BN8: =IF(BL8="","",BL8+($G8*365)) | BP8: =IF(BQ8="","",_xlfn.DAYS(BQ8,$Q$2)) | BQ8: =IF(BO8="","",BO8+($G8*365)) | BS8: =IF(BT8="","",_xlfn.DAYS(BT8,$Q$2)) | BT8: =IF(BR8="","",BR8+($G8*365)) | BV8: =IF(BW8="","",_xlfn.DAYS(BW8,$Q$2)) | BW8: =IF(BU8="","",BU8+($G8*365)) | BY8: =IF(BZ8="","",_xlfn.DAYS(BZ8,$Q$2)) | BZ8: =IF(BX8="","",BX8+($G8*365)) | CB8: =IF(CC8="","",_xlfn.DAYS(CC8,$Q$2)) | CC8: =IF(CA8="","",CA8+($G8*365)) | CE8: =IF(CF8="","",_xlfn.DAYS(CF8,$Q$2)) | CF8: =IF(CD8="","",CD8+($G8*365)) | CH8: =IF(CI8="","",_xlfn.DAYS(CI8,$Q$2)) | CI8: =IF(CG8="","",CG8+($G8*365)) | CK8: =IF(CL8="","",_xlfn.DAYS(CL8,$Q$2)) | CL8: =IF(CJ8="","",CJ8+($G8*365)) | CN8: =IF(CO8="","",_xlfn.DAYS(CO8,$Q$2)) | CO8: =IF(CM8="","",CM8+($G8*365)) | CQ8: =IF(CR8="","",_xlfn.DAYS(CR8,$Q$2)) | CR8: =IF(CP8="","",CP8+($G8*365)) | CT8: =IF(CU8="","",_xlfn.DAYS(CU8,$Q$2)) | CU8: =IF(CS8="","",CS8+($G8*365)) | CW8: =IF(CX8="","",_xlfn.DAYS(CX8,$Q$2)) | CX8: =IF(CV8="","",CV8+($G8*365)) | CZ8: =IF(DA8="","",_xlfn.DAYS(DA8,$Q$2)) | DA8: =IF(CY8="","",CY8+($G8*365)) | DC8: =IF(DD8="","",_xlfn.DAYS(DD8,$Q$2)) | DD8: =IF(DB8="","",DB8+($G8*365)) | DF8: =IF(DG8="","",_xlfn.DAYS(DG8,$Q$2)) | DG8: =IF(DE8="","",DE8+($G8*365)) | DI8: =IF(DJ8="","",_xlfn.DAYS(DJ8,$Q$2)) | DJ8: =IF(DH8="","",DH8+($G8*365)) | DL8: =IF(DM8="","",_xlfn.DAYS(DM8,$Q$2)) | DM8: =IF(DK8="","",DK8+($G8*365)) | DO8: =IF(DP8="","",_xlfn.DAYS(DP8,$Q$2)) | DP8: =IF(DN8="","",DN8+($G8*365)) | DR8: =IF(DS8="","",_xlfn.DAYS(DS8,$Q$2)) | DS8: =IF(DQ8="","",DQ8+($G8*365)) | DU8: =IF(DV8="","",_xlfn.DAYS(DV8,$Q$2)) | DV8: =IF(DT8="","",DT8+($G8*365)) | DX8: =IF(DY8="","",_xlfn.DAYS(DY8,$Q$2)) | DY8: =IF(DW8="","",DW8+($G8*365)) | EA8: =IF(EB8="","",_xlfn.DAYS(EB8,$Q$2)) | EB8: =IF(DZ8="","",DZ8+($G8*365)) | ED8: =IF(EE8="","",_xlfn.DAYS(EE8,$Q$2)) | EE8: =IF(EC8="","",EC8+($G8*365)) | EG8: =IF(EH8="","",_xlfn.DAYS(EH8,$Q$2)) | EH8: =IF(EF8="","",EF8+($G8*365)) | EJ8: =IF(EK8="","",_xlfn.DAYS(EK8,$Q$2)) | EK8: =IF(EI8="","",EI8+($G8*365)) | EM8: =IF(EN8="","",_xlfn.DAYS(EN8,$Q$2)) | EN8: =IF(EL8="","",EL8+($G8*365)) | EP8: =IF(EQ8="","",_xlfn.DAYS(EQ8,$Q$2)) | EQ8: =IF(EO8="","",EO8+($G8*365)) | ES8: =IF(ET8="","",_xlfn.DAYS(ET8,$Q$2)) | ET8: =IF(ER8="","",ER8+($G8*365)) | EV8: =IF(EW8="","",_xlfn.DAYS(EW8,$Q$2)) | EW8: =IF(EU8="","",EU8+($G8*365)) | EY8: =IF(EZ8="","",_xlfn.DAYS(EZ8,$Q$2)) | EZ8: =IF(EX8="","",EX8+($G8*365)) | FB8: =IF(FC8="","",_xlfn.DAYS(FC8,$Q$2)) | FC8: =IF(FA8="","",FA8+($G8*365)) | FE8: =IF(FF8="","",_xlfn.DAYS(FF8,$Q$2)) | FF8: =IF(FD8="","",FD8+($G8*365)) | FH8: =IF(FI8="","",_xlfn.DAYS(FI8,$Q$2)) | FI8: =IF(FG8="","",FG8+($G8*365)) | FK8: =IF(FL8="","",_xlfn.DAYS(FL8,$Q$2)) | FL8: =IF(FJ8="","",FJ8+($G8*365)) | FN8: =IF(FO8="","",_xlfn.DAYS(FO8,$Q$2)) | FO8: =IF(FM8="","",FM8+($G8*365)) | FQ8: =IF(FR8="","",_xlfn.DAYS(FR8,$Q$2)) | FR8: =IF(FP8 = "", "",FP8+($G8*365)) | FT8: =IF(FU8="","",_xlfn.DAYS(FU8,$Q$2)) | FU8: =IF(FS8="","",FS8+($G8*365))
A9: =IF(E9="","",E9*$GA$7) -> 7 | B9: P004189-006 | C9: 308 | D9: =IF(A9="","",A9*C9) -> 2156 | E9: 7 | F9: 10 1507 - 10/14/25 10 1607 - 10/13/26 10 1809 - 1/9/29 10 21H2 - 1/12/27 10 21H2 IoT - 1/13/32 10 22H2 - 10/14/25 11 21H2 - 10/8/24 11 22H2 - 10/14/25 11 23H2 - 11/10/26 | G9: N/A | H9: WIN ENT UPGRADE & SA SNGL 1 License | I9: =IF(COUNTIFS($Q9:$BD9,">270")=0,"",COUNTIFS($Q9:$BD9,">270")) | J9: =IF(COUNTIFS($Q9:$BD9,"<=270")>0,IF(COUNTIFS($Q9:$BD9,"<=270")-COUNTIFS($Q9:$BD9,"<=180")=0,"",COUNTIFS($Q9:$BD9,"<=270")-COUNTIFS($Q9:$BD9,"<=180")),"") | K9: =IF(COUNTIFS($Q9:$BD9,"<=180")>0,IF(COUNTIFS($Q9:$BD9,"<=180")-COUNTIFS($Q9:$BD9,"<=120")=0,"",COUNTIFS($Q9:$BD9,"<=180")-COUNTIFS($Q9:$BD9,"<=120")),"") | L9: =IF(COUNTIFS($Q9:$BD9,"<=120")>0,IF(COUNTIFS($Q9:$BD9,"<=120")-COUNTIFS($Q9:$BD9,"<=90")=0,"",COUNTIFS($Q9:$BD9,"<=120")-COUNTIFS($Q9:$BD9,"<=90")),"") | M9: =IF(COUNTIFS($Q9:$BD9,"<=90")>0,IF(COUNTIFS($Q9:$BD9,"<=90")-COUNTIFS($Q9:$BD9,"<=60")=0,"",COUNTIFS($Q9:$BD9,"<=90")-COUNTIFS($Q9:$BD9,"<=60")),"") | N9: =IF(COUNTIFS($Q9:$BD9,"<=60")>0,IF(COUNTIFS($Q9:$BD9,"<=60")-COUNTIFS($Q9:$BD9,"<=30")=0,"",COUNTIFS($Q9:$BD9,"<=60")-COUNTIFS($Q9:$BD9,"<=30")),"") | O9: =IF(COUNTIFS($Q9:$BD9,"<=30")>0,IF(COUNTIFS($Q9:$BD9,"<=30")-COUNTIFS($Q9:$BD9,"<=0")=0,"",COUNTIFS($Q9:$BD9,"<=30")-COUNTIFS($Q9:$BD9,"<=0")),"") | P9: =IF(COUNTIFS($Q9:$BD9,"<=0")=0,"",COUNTIFS($Q9:$BD9,"<=0")) | Q9: =IF($S$2>0,IF(BG9="","",BG9),"") -> #VALUE! | R9: =IF($S$2>1,IF(BJ9="","",BJ9),"") | S9: =IF($S$2>2,IF(BM9="","",BM9),"") | T9: =IF($S$2>3,IF(BP9="","",BP9),"") | U9: =IF($S$2>4,IF(BS9="","",BS9),"") | V9: =IF($S$2>5,IF(BV9="","",BV9),"") | W9: =IF($S$2>6,IF(BY9="","",BY9),"") | X9: =IF($S$2>7,IF(CB9="","",CB9),"") | Y9: =IF($S$2>8,IF(CE9="","",CE9),"") | Z9: =IF($S$2>9,IF(CH9="","",CH9),"") | AA9: =IF($S$2>10,IF(CK9="","",CK9),"") | AB9: =IF($S$2>11,IF(CN9="","",CN9),"") | AC9: =IF($S$2>12,IF(CQ9="","",CQ9),"") | AD9: =IF($S$2>13,IF(CT9="","",CT9),"") | AE9: =IF($S$2>14,IF(CW9="","",CW9),"") | AF9: =IF($S$2>15,IF(CZ9="","",CZ9),"") | AG9: =IF($S$2>16,IF(DC9="","",DC9),"") | AH9: =IF($S$2>17,IF(DF9="","",DF9),"") | AI9: =IF($S$2>18,IF(DI9 = "","",DI9),"") | AJ9: =IF($S$2>19,IF(DL9="","",DL9),"") | AK9: =IF($S$2>20,IF(DO9="","",DO9),"") | AL9: =IF($S$2>21,IF(DR9="","",DR9),"") | AM9: =IF($S$2>22,IF(DU9="","",DU9),"") | AN9: =IF($S$2>23,IF(DX9="","",DX9),"") | AO9: =IF($S$2>24,IF(EA9="","",EA9),"") | AP9: =IF($S$2>25,IF(ED9="","",ED9),"") | AQ9: =IF($S$2>26,IF(EG9="","",EG9),"") | AR9: =IF($S$2>27,IF(EJ9="","",EJ9),"") | AS9: =IF($S$2>28,IF(EM9="","",EM9),"") | AT9: =IF($S$2>29,IF(EP9 = "", "", EP9),"") | AU9: =IF($S$2>30,IF(ES9="","",ES9),"") | AV9: =IF($S$2>31,IF(EV9="","",EV9),"") | AW9: =IF($S$2>32,IF(EY9="","",EY9),"") | AX9: =IF($S$2>33,IF(FB9="","",FB9),"") | AY9: =IF($S$2>34,IF(FE9="","",FE9),"") | AZ9: =IF($S$2>35,IF(FH9="","",FH9),"") | BA9: =IF($S$2>36,IF(FK9="","",FK9),"") | BB9: =IF($S$2>37,IF(FN9="","",FN9),"") | BC9: =IF($S$2>38,IF(FQ9="","",FQ9),"") | BD9: =IF($S$2>39,IF(FT9="","",FT9),"") | BE9: =IF($S$2>40,IF(FW9="","",FW9),"") | BF9: 45303 | BG9: =IF(BH9="","",_xlfn.DAYS(BH9,$Q$2)) -> #VALUE! | BH9: =IF(BF9="","",BF9+($G9*365)) -> #VALUE! | BJ9: =IF(BK9="","",_xlfn.DAYS(BK9,$Q$2)) | BK9: =IF(BI9="","",BI9+($G9*365)) | BM9: =IF(BN9="","",_xlfn.DAYS(BN9,$Q$2)) | BN9: =IF(BL9="","",BL9+($G9*365)) | BP9: =IF(BQ9="","",_xlfn.DAYS(BQ9,$Q$2)) | BQ9: =IF(BO9="","",BO9+($G9*365)) | BS9: =IF(BT9="","",_xlfn.DAYS(BT9,$Q$2)) | BT9: =IF(BR9="","",BR9+($G9*365)) | BV9: =IF(BW9="","",_xlfn.DAYS(BW9,$Q$2)) | BW9: =IF(BU9="","",BU9+($G9*365)) | BY9: =IF(BZ9="","",_xlfn.DAYS(BZ9,$Q$2)) | BZ9: =IF(BX9="","",BX9+($G9*365)) | CB9: =IF(CC9="","",_xlfn.DAYS(CC9,$Q$2)) | CC9: =IF(CA9="","",CA9+($G9*365)) | CE9: =IF(CF9="","",_xlfn.DAYS(CF9,$Q$2)) | CF9: =IF(CD9="","",CD9+($G9*365)) | CH9: =IF(CI9="","",_xlfn.DAYS(CI9,$Q$2)) | CI9: =IF(CG9="","",CG9+($G9*365)) | CK9: =IF(CL9="","",_xlfn.DAYS(CL9,$Q$2)) | CL9: =IF(CJ9="","",CJ9+($G9*365)) | CN9: =IF(CO9="","",_xlfn.DAYS(CO9,$Q$2)) | CO9: =IF(CM9="","",CM9+($G9*365)) | CQ9: =IF(CR9="","",_xlfn.DAYS(CR9,$Q$2)) | CR9: =IF(CP9="","",CP9+($G9*365)) | CT9: =IF(CU9="","",_xlfn.DAYS(CU9,$Q$2)) | CU9: =IF(CS9="","",CS9+($G9*365)) | CW9: =IF(CX9="","",_xlfn.DAYS(CX9,$Q$2)) | CX9: =IF(CV9="","",CV9+($G9*365)) | CZ9: =IF(DA9="","",_xlfn.DAYS(DA9,$Q$2)) | DA9: =IF(CY9="","",CY9+($G9*365)) | DC9: =IF(DD9="","",_xlfn.DAYS(DD9,$Q$2)) | DD9: =IF(DB9="","",DB9+($G9*365)) | DF9: =IF(DG9="","",_xlfn.DAYS(DG9,$Q$2)) | DG9: =IF(DE9="","",DE9+($G9*365)) | DI9: =IF(DJ9="","",_xlfn.DAYS(DJ9,$Q$2)) | DJ9: =IF(DH9="","",DH9+($G9*365)) | DL9: =IF(DM9="","",_xlfn.DAYS(DM9,$Q$2)) | DM9: =IF(DK9="","",DK9+($G9*365)) | DO9: =IF(DP9="","",_xlfn.DAYS(DP9,$Q$2)) | DP9: =IF(DN9="","",DN9+($G9*365)) | DR9: =IF(DS9="","",_xlfn.DAYS(DS9,$Q$2)) | DS9: =IF(DQ9="","",DQ9+($G9*365)) | DU9: =IF(DV9="","",_xlfn.DAYS(DV9,$Q$2)) | DV9: =IF(DT9="","",DT9+($G9*365)) | DX9: =IF(DY9="","",_xlfn.DAYS(DY9,$Q$2)) | DY9: =IF(DW9="","",DW9+($G9*365)) | EA9: =IF(EB9="","",_xlfn.DAYS(EB9,$Q$2)) | EB9: =IF(DZ9="","",DZ9+($G9*365)) | ED9: =IF(EE9="","",_xlfn.DAYS(EE9,$Q$2)) | EE9: =IF(EC9="","",EC9+($G9*365)) | EG9: =IF(EH9="","",_xlfn.DAYS(EH9,$Q$2)) | EH9: =IF(EF9="","",EF9+($G9*365)) | EJ9: =IF(EK9="","",_xlfn.DAYS(EK9,$Q$2)) | EK9: =IF(EI9="","",EI9+($G9*365)) | EM9: =IF(EN9="","",_xlfn.DAYS(EN9,$Q$2)) | EN9: =IF(EL9="","",EL9+($G9*365)) | EP9: =IF(EQ9="","",_xlfn.DAYS(EQ9,$Q$2)) | EQ9: =IF(EO9="","",EO9+($G9*365)) | ES9: =IF(ET9="","",_xlfn.DAYS(ET9,$Q$2)) | ET9: =IF(ER9="","",ER9+($G9*365)) | EV9: =IF(EW9="","",_xlfn.DAYS(EW9,$Q$2)) | EW9: =IF(EU9="","",EU9+($G9*365)) | EY9: =IF(EZ9="","",_xlfn.DAYS(EZ9,$Q$2)) | EZ9: =IF(EX9="","",EX9+($G9*365)) | FB9: =IF(FC9="","",_xlfn.DAYS(FC9,$Q$2)) | FC9: =IF(FA9="","",FA9+($G9*365)) | FE9: =IF(FF9="","",_xlfn.DAYS(FF9,$Q$2)) | FF9: =IF(FD9="","",FD9+($G9*365)) | FH9: =IF(FI9="","",_xlfn.DAYS(FI9,$Q$2)) | FI9: =IF(FG9="","",FG9+($G9*365)) | FK9: =IF(FL9="","",_xlfn.DAYS(FL9,$Q$2)) | FL9: =IF(FJ9="","",FJ9+($G9*365)) | FN9: =IF(FO9="","",_xlfn.DAYS(FO9,$Q$2)) | FO9: =IF(FM9="","",FM9+($G9*365)) | FQ9: =IF(FR9="","",_xlfn.DAYS(FR9,$Q$2)) | FR9: =IF(FP9 = "", "",FP9+($G9*365)) | FT9: =IF(FU9="","",_xlfn.DAYS(FU9,$Q$2)) | FU9: =IF(FS9="","",FS9+($G9*365))
A10: =IF(E10="","",E10*$GA$7) -> 1 | B10: P010012-003 | C10: 0 | D10: =IF(A10="","",A10*C10) -> 0 | E10: 1 | F10: 2016 - 10/14/25 2019 - 10/14/25 2021 - 10/13/26 365 - Unknown | G10: N/A | H10: O365ProplusDOD ShrdSvr ALNG SubsVL MVL PerUsr | I10: =IF(COUNTIFS($Q10:$BD10,">270")=0,"",COUNTIFS($Q10:$BD10,">270")) | J10: =IF(COUNTIFS($Q10:$BD10,"<=270")>0,IF(COUNTIFS($Q10:$BD10,"<=270")-COUNTIFS($Q10:$BD10,"<=180")=0,"",COUNTIFS($Q10:$BD10,"<=270")-COUNTIFS($Q10:$BD10,"<=180")),"") | K10: =IF(COUNTIFS($Q10:$BD10,"<=180")>0,IF(COUNTIFS($Q10:$BD10,"<=180")-COUNTIFS($Q10:$BD10,"<=120")=0,"",COUNTIFS($Q10:$BD10,"<=180")-COUNTIFS($Q10:$BD10,"<=120")),"") | L10: =IF(COUNTIFS($Q10:$BD10,"<=120")>0,IF(COUNTIFS($Q10:$BD10,"<=120")-COUNTIFS($Q10:$BD10,"<=90")=0,"",COUNTIFS($Q10:$BD10,"<=120")-COUNTIFS($Q10:$BD10,"<=90")),"") | M10: =IF(COUNTIFS($Q10:$BD10,"<=90")>0,IF(COUNTIFS($Q10:$BD10,"<=90")-COUNTIFS($Q10:$BD10,"<=60")=0,"",COUNTIFS($Q10:$BD10,"<=90")-COUNTIFS($Q10:$BD10,"<=60")),"") | N10: =IF(COUNTIFS($Q10:$BD10,"<=60")>0,IF(COUNTIFS($Q10:$BD10,"<=60")-COUNTIFS($Q10:$BD10,"<=30")=0,"",COUNTIFS($Q10:$BD10,"<=60")-COUNTIFS($Q10:$BD10,"<=30")),"") | O10: =IF(COUNTIFS($Q10:$BD10,"<=30")>0,IF(COUNTIFS($Q10:$BD10,"<=30")-COUNTIFS($Q10:$BD10,"<=0")=0,"",COUNTIFS($Q10:$BD10,"<=30")-COUNTIFS($Q10:$BD10,"<=0")),"") | P10: =IF(COUNTIFS($Q10:$BD10,"<=0")=0,"",COUNTIFS($Q10:$BD10,"<=0")) | Q10: =IF($S$2>0,IF(BG10="","",BG10),"") -> #VALUE! | R10: =IF($S$2>1,IF(BJ10="","",BJ10),"") | S10: =IF($S$2>2,IF(BM10="","",BM10),"") | T10: =IF($S$2>3,IF(BP10="","",BP10),"") | U10: =IF($S$2>4,IF(BS10="","",BS10),"") | V10: =IF($S$2>5,IF(BV10="","",BV10),"") | W10: =IF($S$2>6,IF(BY10="","",BY10),"") | X10: =IF($S$2>7,IF(CB10="","",CB10),"") | Y10: =IF($S$2>8,IF(CE10="","",CE10),"") | Z10: =IF($S$2>9,IF(CH10="","",CH10),"") | AA10: =IF($S$2>10,IF(CK10="","",CK10),"") | AB10: =IF($S$2>11,IF(CN10="","",CN10),"") | AC10: =IF($S$2>12,IF(CQ10="","",CQ10),"") | AD10: =IF($S$2>13,IF(CT10="","",CT10),"") | AE10: =IF($S$2>14,IF(CW10="","",CW10),"") | AF10: =IF($S$2>15,IF(CZ10="","",CZ10),"") | AG10: =IF($S$2>16,IF(DC10="","",DC10),"") | AH10: =IF($S$2>17,IF(DF10="","",DF10),"") | AI10: =IF($S$2>18,IF(DI10 = "","",DI10),"") | AJ10: =IF($S$2>19,IF(DL10="","",DL10),"") | AK10: =IF($S$2>20,IF(DO10="","",DO10),"") | AL10: =IF($S$2>21,IF(DR10="","",DR10),"") | AM10: =IF($S$2>22,IF(DU10="","",DU10),"") | AN10: =IF($S$2>23,IF(DX10="","",DX10),"") | AO10: =IF($S$2>24,IF(EA10="","",EA10),"") | AP10: =IF($S$2>25,IF(ED10="","",ED10),"") | AQ10: =IF($S$2>26,IF(EG10="","",EG10),"") | AR10: =IF($S$2>27,IF(EJ10="","",EJ10),"") | AS10: =IF($S$2>28,IF(EM10="","",EM10),"") | AT10: =IF($S$2>29,IF(EP10 = "", "", EP10),"") | AU10: =IF($S$2>30,IF(ES10="","",ES10),"") | AV10: =IF($S$2>31,IF(EV10="","",EV10),"") | AW10: =IF($S$2>32,IF(EY10="","",EY10),"") | AX10: =IF($S$2>33,IF(FB10="","",FB10),"") | AY10: =IF($S$2>34,IF(FE10="","",FE10),"") | AZ10: =IF($S$2>35,IF(FH10="","",FH10),"") | BA10: =IF($S$2>36,IF(FK10="","",FK10),"") | BB10: =IF($S$2>37,IF(FN10="","",FN10),"") | BC10: =IF($S$2>38,IF(FQ10="","",FQ10),"") | BD10: =IF($S$2>39,IF(FT10="","",FT10),"") | BE10: =IF($S$2>40,IF(FW10="","",FW10),"") | BF10: 44938 | BG10: =IF(BH10="","",_xlfn.DAYS(BH10,$Q$2)) -> #VALUE! | BH10: =IF(BF10="","",BF10+($G10*365)) -> #VALUE! | BJ10: =IF(BK10="","",_xlfn.DAYS(BK10,$Q$2)) | BK10: =IF(BI10="","",BI10+($G10*365)) | BM10: =IF(BN10="","",_xlfn.DAYS(BN10,$Q$2)) | BN10: =IF(BL10="","",BL10+($G10*365)) | BP10: =IF(BQ10="","",_xlfn.DAYS(BQ10,$Q$2)) | BQ10: =IF(BO10="","",BO10+($G10*365)) | BS10: =IF(BT10="","",_xlfn.DAYS(BT10,$Q$2)) | BT10: =IF(BR10="","",BR10+($G10*365)) | BV10: =IF(BW10="","",_xlfn.DAYS(BW10,$Q$2)) | BW10: =IF(BU10="","",BU10+($G10*365)) | BY10: =IF(BZ10="","",_xlfn.DAYS(BZ10,$Q$2)) | BZ10: =IF(BX10="","",BX10+($G10*365)) | CB10: =IF(CC10="","",_xlfn.DAYS(CC10,$Q$2)) | CC10: =IF(CA10="","",CA10+($G10*365)) | CE10: =IF(CF10="","",_xlfn.DAYS(CF10,$Q$2)) | CF10: =IF(CD10="","",CD10+($G10*365)) | CH10: =IF(CI10="","",_xlfn.DAYS(CI10,$Q$2)) | CI10: =IF(CG10="","",CG10+($G10*365)) | CK10: =IF(CL10="","",_xlfn.DAYS(CL10,$Q$2)) | CL10: =IF(CJ10="","",CJ10+($G10*365)) | CN10: =IF(CO10="","",_xlfn.DAYS(CO10,$Q$2)) | CO10: =IF(CM10="","",CM10+($G10*365)) | CQ10: =IF(CR10="","",_xlfn.DAYS(CR10,$Q$2)) | CR10: =IF(CP10="","",CP10+($G10*365)) | CT10: =IF(CU10="","",_xlfn.DAYS(CU10,$Q$2)) | CU10: =IF(CS10="","",CS10+($G10*365)) | CW10: =IF(CX10="","",_xlfn.DAYS(CX10,$Q$2)) | CX10: =IF(CV10="","",CV10+($G10*365)) | CZ10: =IF(DA10="","",_xlfn.DAYS(DA10,$Q$2)) | DA10: =IF(CY10="","",CY10+($G10*365)) | DC10: =IF(DD10="","",_xlfn.DAYS(DD10,$Q$2)) | DD10: =IF(DB10="","",DB10+($G10*365)) | DF10: =IF(DG10="","",_xlfn.DAYS(DG10,$Q$2)) | DG10: =IF(DE10="","",DE10+($G10*365)) | DI10: =IF(DJ10="","",_xlfn.DAYS(DJ10,$Q$2)) | DJ10: =IF(DH10="","",DH10+($G10*365)) | DL10: =IF(DM10="","",_xlfn.DAYS(DM10,$Q$2)) | DM10: =IF(DK10="","",DK10+($G10*365)) | DO10: =IF(DP10="","",_xlfn.DAYS(DP10,$Q$2)) | DP10: =IF(DN10="","",DN10+($G10*365)) | DR10: =IF(DS10="","",_xlfn.DAYS(DS10,$Q$2)) | DS10: =IF(DQ10="","",DQ10+($G10*365)) | DU10: =IF(DV10="","",_xlfn.DAYS(DV10,$Q$2)) | DV10: =IF(DT10="","",DT10+($G10*365)) | DX10: =IF(DY10="","",_xlfn.DAYS(DY10,$Q$2)) | DY10: =IF(DW10="","",DW10+($G10*365)) | EA10: =IF(EB10="","",_xlfn.DAYS(EB10,$Q$2)) | EB10: =IF(DZ10="","",DZ10+($G10*365)) | ED10: =IF(EE10="","",_xlfn.DAYS(EE10,$Q$2)) | EE10: =IF(EC10="","",EC10+($G10*365)) | EG10: =IF(EH10="","",_xlfn.DAYS(EH10,$Q$2)) | EH10: =IF(EF10="","",EF10+($G10*365)) | EJ10: =IF(EK10="","",_xlfn.DAYS(EK10,$Q$2)) | EK10: =IF(EI10="","",EI10+($G10*365)) | EM10: =IF(EN10="","",_xlfn.DAYS(EN10,$Q$2)) | EN10: =IF(EL10="","",EL10+($G10*365)) | EP10: =IF(EQ10="","",_xlfn.DAYS(EQ10,$Q$2)) | EQ10: =IF(EO10="","",EO10+($G10*365)) | ES10: =IF(ET10="","",_xlfn.DAYS(ET10,$Q$2)) | ET10: =IF(ER10="","",ER10+($G10*365)) | EV10: =IF(EW10="","",_xlfn.DAYS(EW10,$Q$2)) | EW10: =IF(EU10="","",EU10+($G10*365)) | EY10: =IF(EZ10="","",_xlfn.DAYS(EZ10,$Q$2)) | EZ10: =IF(EX10="","",EX10+($G10*365)) | FB10: =IF(FC10="","",_xlfn.DAYS(FC10,$Q$2)) | FC10: =IF(FA10="","",FA10+($G10*365)) | FE10: =IF(FF10="","",_xlfn.DAYS(FF10,$Q$2)) | FF10: =IF(FD10="","",FD10+($G10*365)) | FH10: =IF(FI10="","",_xlfn.DAYS(FI10,$Q$2)) | FI10: =IF(FG10="","",FG10+($G10*365)) | FK10: =IF(FL10="","",_xlfn.DAYS(FL10,$Q$2)) | FL10: =IF(FJ10="","",FJ10+($G10*365)) | FN10: =IF(FO10="","",_xlfn.DAYS(FO10,$Q$2)) | FO10: =IF(FM10="","",FM10+($G10*365)) | FQ10: =IF(FR10="","",_xlfn.DAYS(FR10,$Q$2)) | FR10: =IF(FP10 = "", "",FP10+($G10*365)) | FT10: =IF(FU10="","",_xlfn.DAYS(FU10,$Q$2)) | FU10: =IF(FS10="","",FS10+($G10*365))
A11: =IF(E11="","",E11*$GA$7) -> 3 | B11: P007732-001 | C11: 565 | D11: =IF(A11="","",A11*C11) -> 1695 | E11: 3 | F11: RHEL7 - 6/30/24 RHEL8 - 5/31/29 RHEL9 - 10/31/32 | G11: 1 | H11: Subscription - Red Hat Enterprise Linux Server Standard | I11: =IF(COUNTIFS($Q11:$BD11,">270")=0,"",COUNTIFS($Q11:$BD11,">270")) | J11: =IF(COUNTIFS($Q11:$BD11,"<=270")>0,IF(COUNTIFS($Q11:$BD11,"<=270")-COUNTIFS($Q11:$BD11,"<=180")=0,"",COUNTIFS($Q11:$BD11,"<=270")-COUNTIFS($Q11:$BD11,"<=180")),"") | K11: =IF(COUNTIFS($Q11:$BD11,"<=180")>0,IF(COUNTIFS($Q11:$BD11,"<=180")-COUNTIFS($Q11:$BD11,"<=120")=0,"",COUNTIFS($Q11:$BD11,"<=180")-COUNTIFS($Q11:$BD11,"<=120")),"") | L11: =IF(COUNTIFS($Q11:$BD11,"<=120")>0,IF(COUNTIFS($Q11:$BD11,"<=120")-COUNTIFS($Q11:$BD11,"<=90")=0,"",COUNTIFS($Q11:$BD11,"<=120")-COUNTIFS($Q11:$BD11,"<=90")),"") | M11: =IF(COUNTIFS($Q11:$BD11,"<=90")>0,IF(COUNTIFS($Q11:$BD11,"<=90")-COUNTIFS($Q11:$BD11,"<=60")=0,"",COUNTIFS($Q11:$BD11,"<=90")-COUNTIFS($Q11:$BD11,"<=60")),"") | N11: =IF(COUNTIFS($Q11:$BD11,"<=60")>0,IF(COUNTIFS($Q11:$BD11,"<=60")-COUNTIFS($Q11:$BD11,"<=30")=0,"",COUNTIFS($Q11:$BD11,"<=60")-COUNTIFS($Q11:$BD11,"<=30")),"") | O11: =IF(COUNTIFS($Q11:$BD11,"<=30")>0,IF(COUNTIFS($Q11:$BD11,"<=30")-COUNTIFS($Q11:$BD11,"<=0")=0,"",COUNTIFS($Q11:$BD11,"<=30")-COUNTIFS($Q11:$BD11,"<=0")),"") | P11: =IF(COUNTIFS($Q11:$BD11,"<=0")=0,"",COUNTIFS($Q11:$BD11,"<=0")) -> 1 | Q11: =IF($S$2>0,IF(BG11="","",BG11),"") -> -7 | R11: =IF($S$2>1,IF(BJ11="","",BJ11),"") | S11: =IF($S$2>2,IF(BM11="","",BM11),"") | T11: =IF($S$2>3,IF(BP11="","",BP11),"") | U11: =IF($S$2>4,IF(BS11="","",BS11),"") | V11: =IF($S$2>5,IF(BV11="","",BV11),"") | W11: =IF($S$2>6,IF(BY11="","",BY11),"") | X11: =IF($S$2>7,IF(CB11="","",CB11),"") | Y11: =IF($S$2>8,IF(CE11="","",CE11),"") | Z11: =IF($S$2>9,IF(CH11="","",CH11),"") | AA11: =IF($S$2>10,IF(CK11="","",CK11),"") | AB11: =IF($S$2>11,IF(CN11="","",CN11),"") | AC11: =IF($S$2>12,IF(CQ11="","",CQ11),"") | AD11: =IF($S$2>13,IF(CT11="","",CT11),"") | AE11: =IF($S$2>14,IF(CW11="","",CW11),"") | AF11: =IF($S$2>15,IF(CZ11="","",CZ11),"") | AG11: =IF($S$2>16,IF(DC11="","",DC11),"") | AH11: =IF($S$2>17,IF(DF11="","",DF11),"") | AI11: =IF($S$2>18,IF(DI11 = "","",DI11),"") | AJ11: =IF($S$2>19,IF(DL11="","",DL11),"") | AK11: =IF($S$2>20,IF(DO11="","",DO11),"") | AL11: =IF($S$2>21,IF(DR11="","",DR11),"") | AM11: =IF($S$2>22,IF(DU11="","",DU11),"") | AN11: =IF($S$2>23,IF(DX11="","",DX11),"") | AO11: =IF($S$2>24,IF(EA11="","",EA11),"") | AP11: =IF($S$2>25,IF(ED11="","",ED11),"") | AQ11: =IF($S$2>26,IF(EG11="","",EG11),"") | AR11: =IF($S$2>27,IF(EJ11="","",EJ11),"") | AS11: =IF($S$2>28,IF(EM11="","",EM11),"") | AT11: =IF($S$2>29,IF(EP11 = "", "", EP11),"") | AU11: =IF($S$2>30,IF(ES11="","",ES11),"") | AV11: =IF($S$2>31,IF(EV11="","",EV11),"") | AW11: =IF($S$2>32,IF(EY11="","",EY11),"") | AX11: =IF($S$2>33,IF(FB11="","",FB11),"") | AY11: =IF($S$2>34,IF(FE11="","",FE11),"") | AZ11: =IF($S$2>35,IF(FH11="","",FH11),"") | BA11: =IF($S$2>36,IF(FK11="","",FK11),"") | BB11: =IF($S$2>37,IF(FN11="","",FN11),"") | BC11: =IF($S$2>38,IF(FQ11="","",FQ11),"") | BD11: =IF($S$2>39,IF(FT11="","",FT11),"") | BE11: =IF($S$2>40,IF(FW11="","",FW11),"") | BF11: 45559 | BG11: =IF(BH11="","",_xlfn.DAYS(BH11,$Q$2)) -> -7 | BH11: =IF(BF11="","",BF11+($G11*365)) -> 45924 | BJ11: =IF(BK11="","",_xlfn.DAYS(BK11,$Q$2)) | BK11: =IF(BI11="","",BI11+($G11*365)) | BM11: =IF(BN11="","",_xlfn.DAYS(BN11,$Q$2)) | BN11: =IF(BL11="","",BL11+($G11*365)) | BP11: =IF(BQ11="","",_xlfn.DAYS(BQ11,$Q$2)) | BQ11: =IF(BO11="","",BO11+($G11*365)) | BS11: =IF(BT11="","",_xlfn.DAYS(BT11,$Q$2)) | BT11: =IF(BR11="","",BR11+($G11*365)) | BV11: =IF(BW11="","",_xlfn.DAYS(BW11,$Q$2)) | BW11: =IF(BU11="","",BU11+($G11*365)) | BY11: =IF(BZ11="","",_xlfn.DAYS(BZ11,$Q$2)) | BZ11: =IF(BX11="","",BX11+($G11*365)) | CB11: =IF(CC11="","",_xlfn.DAYS(CC11,$Q$2)) | CC11: =IF(CA11="","",CA11+($G11*365)) | CE11: =IF(CF11="","",_xlfn.DAYS(CF11,$Q$2)) | CF11: =IF(CD11="","",CD11+($G11*365)) | CH11: =IF(CI11="","",_xlfn.DAYS(CI11,$Q$2)) | CI11: =IF(CG11="","",CG11+($G11*365)) | CK11: =IF(CL11="","",_xlfn.DAYS(CL11,$Q$2)) | CL11: =IF(CJ11="","",CJ11+($G11*365)) | CN11: =IF(CO11="","",_xlfn.DAYS(CO11,$Q$2)) | CO11: =IF(CM11="","",CM11+($G11*365)) | CQ11: =IF(CR11="","",_xlfn.DAYS(CR11,$Q$2)) | CR11: =IF(CP11="","",CP11+($G11*365)) | CT11: =IF(CU11="","",_xlfn.DAYS(CU11,$Q$2)) | CU11: =IF(CS11="","",CS11+($G11*365)) | CW11: =IF(CX11="","",_xlfn.DAYS(CX11,$Q$2)) | CX11: =IF(CV11="","",CV11+($G11*365)) | CZ11: =IF(DA11="","",_xlfn.DAYS(DA11,$Q$2)) | DA11: =IF(CY11="","",CY11+($G11*365)) | DC11: =IF(DD11="","",_xlfn.DAYS(DD11,$Q$2)) | DD11: =IF(DB11="","",DB11+($G11*365)) | DF11: =IF(DG11="","",_xlfn.DAYS(DG11,$Q$2)) | DG11: =IF(DE11="","",DE11+($G11*365)) | DI11: =IF(DJ11="","",_xlfn.DAYS(DJ11,$Q$2)) | DJ11: =IF(DH11="","",DH11+($G11*365)) | DL11: =IF(DM11="","",_xlfn.DAYS(DM11,$Q$2)) | DM11: =IF(DK11="","",DK11+($G11*365)) | DO11: =IF(DP11="","",_xlfn.DAYS(DP11,$Q$2)) | DP11: =IF(DN11="","",DN11+($G11*365)) | DR11: =IF(DS11="","",_xlfn.DAYS(DS11,$Q$2)) | DS11: =IF(DQ11="","",DQ11+($G11*365)) | DU11: =IF(DV11="","",_xlfn.DAYS(DV11,$Q$2)) | DV11: =IF(DT11="","",DT11+($G11*365)) | DX11: =IF(DY11="","",_xlfn.DAYS(DY11,$Q$2)) | DY11: =IF(DW11="","",DW11+($G11*365)) | EA11: =IF(EB11="","",_xlfn.DAYS(EB11,$Q$2)) | EB11: =IF(DZ11="","",DZ11+($G11*365)) | ED11: =IF(EE11="","",_xlfn.DAYS(EE11,$Q$2)) | EE11: =IF(EC11="","",EC11+($G11*365)) | EG11: =IF(EH11="","",_xlfn.DAYS(EH11,$Q$2)) | EH11: =IF(EF11="","",EF11+($G11*365)) | EJ11: =IF(EK11="","",_xlfn.DAYS(EK11,$Q$2)) | EK11: =IF(EI11="","",EI11+($G11*365)) | EM11: =IF(EN11="","",_xlfn.DAYS(EN11,$Q$2)) | EN11: =IF(EL11="","",EL11+($G11*365)) | EP11: =IF(EQ11="","",_xlfn.DAYS(EQ11,$Q$2)) | EQ11: =IF(EO11="","",EO11+($G11*365)) | ES11: =IF(ET11="","",_xlfn.DAYS(ET11,$Q$2)) | ET11: =IF(ER11="","",ER11+($G11*365)) | EV11: =IF(EW11="","",_xlfn.DAYS(EW11,$Q$2)) | EW11: =IF(EU11="","",EU11+($G11*365)) | EY11: =IF(EZ11="","",_xlfn.DAYS(EZ11,$Q$2)) | EZ11: =IF(EX11="","",EX11+($G11*365)) | FB11: =IF(FC11="","",_xlfn.DAYS(FC11,$Q$2)) | FC11: =IF(FA11="","",FA11+($G11*365)) | FE11: =IF(FF11="","",_xlfn.DAYS(FF11,$Q$2)) | FF11: =IF(FD11="","",FD11+($G11*365)) | FH11: =IF(FI11="","",_xlfn.DAYS(FI11,$Q$2)) | FI11: =IF(FG11="","",FG11+($G11*365)) | FK11: =IF(FL11="","",_xlfn.DAYS(FL11,$Q$2)) | FL11: =IF(FJ11="","",FJ11+($G11*365)) | FN11: =IF(FO11="","",_xlfn.DAYS(FO11,$Q$2)) | FO11: =IF(FM11="","",FM11+($G11*365)) | FQ11: =IF(FR11="","",_xlfn.DAYS(FR11,$Q$2)) | FR11: =IF(FP11 = "", "",FP11+($G11*365)) | FT11: =IF(FU11="","",_xlfn.DAYS(FU11,$Q$2)) | FU11: =IF(FS11="","",FS11+($G11*365)) | FV11: Contract #: 17175003
A12: =IF(E12="","",E12*$GA$7) -> 3 | B12: P011098-001 | C12: 318 | D12: =IF(A12="","",A12*C12) -> 954 | E12: 3 | G12: N/A | H12: Software Maintenance - Extended Life Cycle Support (ELS) Red Hat | I12: =IF(COUNTIFS($Q12:$BD12,">270")=0,"",COUNTIFS($Q12:$BD12,">270")) | J12: =IF(COUNTIFS($Q12:$BD12,"<=270")>0,IF(COUNTIFS($Q12:$BD12,"<=270")-COUNTIFS($Q12:$BD12,"<=180")=0,"",COUNTIFS($Q12:$BD12,"<=270")-COUNTIFS($Q12:$BD12,"<=180")),"") | K12: =IF(COUNTIFS($Q12:$BD12,"<=180")>0,IF(COUNTIFS($Q12:$BD12,"<=180")-COUNTIFS($Q12:$BD12,"<=120")=0,"",COUNTIFS($Q12:$BD12,"<=180")-COUNTIFS($Q12:$BD12,"<=120")),"") | L12: =IF(COUNTIFS($Q12:$BD12,"<=120")>0,IF(COUNTIFS($Q12:$BD12,"<=120")-COUNTIFS($Q12:$BD12,"<=90")=0,"",COUNTIFS($Q12:$BD12,"<=120")-COUNTIFS($Q12:$BD12,"<=90")),"") | M12: =IF(COUNTIFS($Q12:$BD12,"<=90")>0,IF(COUNTIFS($Q12:$BD12,"<=90")-COUNTIFS($Q12:$BD12,"<=60")=0,"",COUNTIFS($Q12:$BD12,"<=90")-COUNTIFS($Q12:$BD12,"<=60")),"") | N12: =IF(COUNTIFS($Q12:$BD12,"<=60")>0,IF(COUNTIFS($Q12:$BD12,"<=60")-COUNTIFS($Q12:$BD12,"<=30")=0,"",COUNTIFS($Q12:$BD12,"<=60")-COUNTIFS($Q12:$BD12,"<=30")),"") | O12: =IF(COUNTIFS($Q12:$BD12,"<=30")>0,IF(COUNTIFS($Q12:$BD12,"<=30")-COUNTIFS($Q12:$BD12,"<=0")=0,"",COUNTIFS($Q12:$BD12,"<=30")-COUNTIFS($Q12:$BD12,"<=0")),"") | P12: =IF(COUNTIFS($Q12:$BD12,"<=0")=0,"",COUNTIFS($Q12:$BD12,"<=0")) | Q12: =IF($S$2>0,IF(BG12="","",BG12),"") -> #VALUE! | R12: =IF($S$2>1,IF(BJ12="","",BJ12),"") | S12: =IF($S$2>2,IF(BM12="","",BM12),"") | T12: =IF($S$2>3,IF(BP12="","",BP12),"") | U12: =IF($S$2>4,IF(BS12="","",BS12),"") | V12: =IF($S$2>5,IF(BV12="","",BV12),"") | W12: =IF($S$2>6,IF(BY12="","",BY12),"") | X12: =IF($S$2>7,IF(CB12="","",CB12),"") | Y12: =IF($S$2>8,IF(CE12="","",CE12),"") | Z12: =IF($S$2>9,IF(CH12="","",CH12),"") | AA12: =IF($S$2>10,IF(CK12="","",CK12),"") | AB12: =IF($S$2>11,IF(CN12="","",CN12),"") | AC12: =IF($S$2>12,IF(CQ12="","",CQ12),"") | AD12: =IF($S$2>13,IF(CT12="","",CT12),"") | AE12: =IF($S$2>14,IF(CW12="","",CW12),"") | AF12: =IF($S$2>15,IF(CZ12="","",CZ12),"") | AG12: =IF($S$2>16,IF(DC12="","",DC12),"") | AH12: =IF($S$2>17,IF(DF12="","",DF12),"") | AI12: =IF($S$2>18,IF(DI12 = "","",DI12),"") | AJ12: =IF($S$2>19,IF(DL12="","",DL12),"") | AK12: =IF($S$2>20,IF(DO12="","",DO12),"") | AL12: =IF($S$2>21,IF(DR12="","",DR12),"") | AM12: =IF($S$2>22,IF(DU12="","",DU12),"") | AN12: =IF($S$2>23,IF(DX12="","",DX12),"") | AO12: =IF($S$2>24,IF(EA12="","",EA12),"") | AP12: =IF($S$2>25,IF(ED12="","",ED12),"") | AQ12: =IF($S$2>26,IF(EG12="","",EG12),"") | AR12: =IF($S$2>27,IF(EJ12="","",EJ12),"") | AS12: =IF($S$2>28,IF(EM12="","",EM12),"") | AT12: =IF($S$2>29,IF(EP12 = "", "", EP12),"") | AU12: =IF($S$2>30,IF(ES12="","",ES12),"") | AV12: =IF($S$2>31,IF(EV12="","",EV12),"") | AW12: =IF($S$2>32,IF(EY12="","",EY12),"") | AX12: =IF($S$2>33,IF(FB12="","",FB12),"") | AY12: =IF($S$2>34,IF(FE12="","",FE12),"") | AZ12: =IF($S$2>35,IF(FH12="","",FH12),"") | BA12: =IF($S$2>36,IF(FK12="","",FK12),"") | BB12: =IF($S$2>37,IF(FN12="","",FN12),"") | BC12: =IF($S$2>38,IF(FQ12="","",FQ12),"") | BD12: =IF($S$2>39,IF(FT12="","",FT12),"") | BE12: =IF($S$2>40,IF(FW12="","",FW12),"") | BF12: 45468 | BG12: =IF(BH12="","",_xlfn.DAYS(BH12,$Q$2)) -> #VALUE! | BH12: =IF(BF12="","",BF12+($G12*365)) -> #VALUE! | BJ12: =IF(BK12="","",_xlfn.DAYS(BK12,$Q$2)) | BK12: =IF(BI12="","",BI12+($G12*365)) | BM12: =IF(BN12="","",_xlfn.DAYS(BN12,$Q$2)) | BN12: =IF(BL12="","",BL12+($G12*365)) | BP12: =IF(BQ12="","",_xlfn.DAYS(BQ12,$Q$2)) | BQ12: =IF(BO12="","",BO12+($G12*365)) | BS12: =IF(BT12="","",_xlfn.DAYS(BT12,$Q$2)) | BT12: =IF(BR12="","",BR12+($G12*365)) | BV12: =IF(BW12="","",_xlfn.DAYS(BW12,$Q$2)) | BW12: =IF(BU12="","",BU12+($G12*365)) | BY12: =IF(BZ12="","",_xlfn.DAYS(BZ12,$Q$2)) | BZ12: =IF(BX12="","",BX12+($G12*365)) | CB12: =IF(CC12="","",_xlfn.DAYS(CC12,$Q$2)) | CC12: =IF(CA12="","",CA12+($G12*365)) | CE12: =IF(CF12="","",_xlfn.DAYS(CF12,$Q$2)) | CF12: =IF(CD12="","",CD12+($G12*365)) | CH12: =IF(CI12="","",_xlfn.DAYS(CI12,$Q$2)) | CI12: =IF(CG12="","",CG12+($G12*365)) | CK12: =IF(CL12="","",_xlfn.DAYS(CL12,$Q$2)) | CL12: =IF(CJ12="","",CJ12+($G12*365)) | CN12: =IF(CO12="","",_xlfn.DAYS(CO12,$Q$2)) | CO12: =IF(CM12="","",CM12+($G12*365)) | CQ12: =IF(CR12="","",_xlfn.DAYS(CR12,$Q$2)) | CR12: =IF(CP12="","",CP12+($G12*365)) | CT12: =IF(CU12="","",_xlfn.DAYS(CU12,$Q$2)) | CU12: =IF(CS12="","",CS12+($G12*365)) | CW12: =IF(CX12="","",_xlfn.DAYS(CX12,$Q$2)) | CX12: =IF(CV12="","",CV12+($G12*365)) | CZ12: =IF(DA12="","",_xlfn.DAYS(DA12,$Q$2)) | DA12: =IF(CY12="","",CY12+($G12*365)) | DC12: =IF(DD12="","",_xlfn.DAYS(DD12,$Q$2)) | DD12: =IF(DB12="","",DB12+($G12*365)) | DF12: =IF(DG12="","",_xlfn.DAYS(DG12,$Q$2)) | DG12: =IF(DE12="","",DE12+($G12*365)) | DI12: =IF(DJ12="","",_xlfn.DAYS(DJ12,$Q$2)) | DJ12: =IF(DH12="","",DH12+($G12*365)) | DL12: =IF(DM12="","",_xlfn.DAYS(DM12,$Q$2)) | DM12: =IF(DK12="","",DK12+($G12*365)) | DO12: =IF(DP12="","",_xlfn.DAYS(DP12,$Q$2)) | DP12: =IF(DN12="","",DN12+($G12*365)) | DR12: =IF(DS12="","",_xlfn.DAYS(DS12,$Q$2)) | DS12: =IF(DQ12="","",DQ12+($G12*365)) | DU12: =IF(DV12="","",_xlfn.DAYS(DV12,$Q$2)) | DV12: =IF(DT12="","",DT12+($G12*365)) | DX12: =IF(DY12="","",_xlfn.DAYS(DY12,$Q$2)) | DY12: =IF(DW12="","",DW12+($G12*365)) | EA12: =IF(EB12="","",_xlfn.DAYS(EB12,$Q$2)) | EB12: =IF(DZ12="","",DZ12+($G12*365)) | ED12: =IF(EE12="","",_xlfn.DAYS(EE12,$Q$2)) | EE12: =IF(EC12="","",EC12+($G12*365)) | EG12: =IF(EH12="","",_xlfn.DAYS(EH12,$Q$2)) | EH12: =IF(EF12="","",EF12+($G12*365)) | EJ12: =IF(EK12="","",_xlfn.DAYS(EK12,$Q$2)) | EK12: =IF(EI12="","",EI12+($G12*365)) | EM12: =IF(EN12="","",_xlfn.DAYS(EN12,$Q$2)) | EN12: =IF(EL12="","",EL12+($G12*365)) | EP12: =IF(EQ12="","",_xlfn.DAYS(EQ12,$Q$2)) | EQ12: =IF(EO12="","",EO12+($G12*365)) | ES12: =IF(ET12="","",_xlfn.DAYS(ET12,$Q$2)) | ET12: =IF(ER12="","",ER12+($G12*365)) | EV12: =IF(EW12="","",_xlfn.DAYS(EW12,$Q$2)) | EW12: =IF(EU12="","",EU12+($G12*365)) | EY12: =IF(EZ12="","",_xlfn.DAYS(EZ12,$Q$2)) | EZ12: =IF(EX12="","",EX12+($G12*365)) | FB12: =IF(FC12="","",_xlfn.DAYS(FC12,$Q$2)) | FC12: =IF(FA12="","",FA12+($G12*365)) | FE12: =IF(FF12="","",_xlfn.DAYS(FF12,$Q$2)) | FF12: =IF(FD12="","",FD12+($G12*365)) | FH12: =IF(FI12="","",_xlfn.DAYS(FI12,$Q$2)) | FI12: =IF(FG12="","",FG12+($G12*365)) | FK12: =IF(FL12="","",_xlfn.DAYS(FL12,$Q$2)) | FL12: =IF(FJ12="","",FJ12+($G12*365)) | FN12: =IF(FO12="","",_xlfn.DAYS(FO12,$Q$2)) | FO12: =IF(FM12="","",FM12+($G12*365)) | FQ12: =IF(FR12="","",_xlfn.DAYS(FR12,$Q$2)) | FR12: =IF(FP12 = "", "",FP12+($G12*365)) | FT12: =IF(FU12="","",_xlfn.DAYS(FU12,$Q$2)) | FU12: =IF(FS12="","",FS12+($G12*365))
A13: =IF(E13="","",E13*$GA$7) -> 1 | B13: P011006-001 | C13: 0 | D13: =IF(A13="","",A13*C13) -> 0 | E13: 1 | G13: N/A | H13: SharePointSvr ALNG LicSAPk MVL | I13: =IF(COUNTIFS($Q13:$BD13,">270")=0,"",COUNTIFS($Q13:$BD13,">270")) | J13: =IF(COUNTIFS($Q13:$BD13,"<=270")>0,IF(COUNTIFS($Q13:$BD13,"<=270")-COUNTIFS($Q13:$BD13,"<=180")=0,"",COUNTIFS($Q13:$BD13,"<=270")-COUNTIFS($Q13:$BD13,"<=180")),"") | K13: =IF(COUNTIFS($Q13:$BD13,"<=180")>0,IF(COUNTIFS($Q13:$BD13,"<=180")-COUNTIFS($Q13:$BD13,"<=120")=0,"",COUNTIFS($Q13:$BD13,"<=180")-COUNTIFS($Q13:$BD13,"<=120")),"") | L13: =IF(COUNTIFS($Q13:$BD13,"<=120")>0,IF(COUNTIFS($Q13:$BD13,"<=120")-COUNTIFS($Q13:$BD13,"<=90")=0,"",COUNTIFS($Q13:$BD13,"<=120")-COUNTIFS($Q13:$BD13,"<=90")),"") | M13: =IF(COUNTIFS($Q13:$BD13,"<=90")>0,IF(COUNTIFS($Q13:$BD13,"<=90")-COUNTIFS($Q13:$BD13,"<=60")=0,"",COUNTIFS($Q13:$BD13,"<=90")-COUNTIFS($Q13:$BD13,"<=60")),"") | N13: =IF(COUNTIFS($Q13:$BD13,"<=60")>0,IF(COUNTIFS($Q13:$BD13,"<=60")-COUNTIFS($Q13:$BD13,"<=30")=0,"",COUNTIFS($Q13:$BD13,"<=60")-COUNTIFS($Q13:$BD13,"<=30")),"") | O13: =IF(COUNTIFS($Q13:$BD13,"<=30")>0,IF(COUNTIFS($Q13:$BD13,"<=30")-COUNTIFS($Q13:$BD13,"<=0")=0,"",COUNTIFS($Q13:$BD13,"<=30")-COUNTIFS($Q13:$BD13,"<=0")),"") | P13: =IF(COUNTIFS($Q13:$BD13,"<=0")=0,"",COUNTIFS($Q13:$BD13,"<=0")) | Q13: =IF($S$2>0,IF(BG13="","",BG13),"") -> #VALUE! | R13: =IF($S$2>1,IF(BJ13="","",BJ13),"") | S13: =IF($S$2>2,IF(BM13="","",BM13),"") | T13: =IF($S$2>3,IF(BP13="","",BP13),"") | U13: =IF($S$2>4,IF(BS13="","",BS13),"") | V13: =IF($S$2>5,IF(BV13="","",BV13),"") | W13: =IF($S$2>6,IF(BY13="","",BY13),"") | X13: =IF($S$2>7,IF(CB13="","",CB13),"") | Y13: =IF($S$2>8,IF(CE13="","",CE13),"") | Z13: =IF($S$2>9,IF(CH13="","",CH13),"") | AA13: =IF($S$2>10,IF(CK13="","",CK13),"") | AB13: =IF($S$2>11,IF(CN13="","",CN13),"") | AC13: =IF($S$2>12,IF(CQ13="","",CQ13),"") | AD13: =IF($S$2>13,IF(CT13="","",CT13),"") | AE13: =IF($S$2>14,IF(CW13="","",CW13),"") | AF13: =IF($S$2>15,IF(CZ13="","",CZ13),"") | AG13: =IF($S$2>16,IF(DC13="","",DC13),"") | AH13: =IF($S$2>17,IF(DF13="","",DF13),"") | AI13: =IF($S$2>18,IF(DI13 = "","",DI13),"") | AJ13: =IF($S$2>19,IF(DL13="","",DL13),"") | AK13: =IF($S$2>20,IF(DO13="","",DO13),"") | AL13: =IF($S$2>21,IF(DR13="","",DR13),"") | AM13: =IF($S$2>22,IF(DU13="","",DU13),"") | AN13: =IF($S$2>23,IF(DX13="","",DX13),"") | AO13: =IF($S$2>24,IF(EA13="","",EA13),"") | AP13: =IF($S$2>25,IF(ED13="","",ED13),"") | AQ13: =IF($S$2>26,IF(EG13="","",EG13),"") | AR13: =IF($S$2>27,IF(EJ13="","",EJ13),"") | AS13: =IF($S$2>28,IF(EM13="","",EM13),"") | AT13: =IF($S$2>29,IF(EP13 = "", "", EP13),"") | AU13: =IF($S$2>30,IF(ES13="","",ES13),"") | AV13: =IF($S$2>31,IF(EV13="","",EV13),"") | AW13: =IF($S$2>32,IF(EY13="","",EY13),"") | AX13: =IF($S$2>33,IF(FB13="","",FB13),"") | AY13: =IF($S$2>34,IF(FE13="","",FE13),"") | AZ13: =IF($S$2>35,IF(FH13="","",FH13),"") | BA13: =IF($S$2>36,IF(FK13="","",FK13),"") | BB13: =IF($S$2>37,IF(FN13="","",FN13),"") | BC13: =IF($S$2>38,IF(FQ13="","",FQ13),"") | BD13: =IF($S$2>39,IF(FT13="","",FT13),"") | BE13: =IF($S$2>40,IF(FW13="","",FW13),"") | BF13: 45305 | BG13: =IF(BH13="","",_xlfn.DAYS(BH13,$Q$2)) -> #VALUE! | BH13: =IF(BF13="","",BF13+($G13*365)) -> #VALUE! | BJ13: =IF(BK13="","",_xlfn.DAYS(BK13,$Q$2)) | BK13: =IF(BI13="","",BI13+($G13*365)) | BM13: =IF(BN13="","",_xlfn.DAYS(BN13,$Q$2)) | BN13: =IF(BL13="","",BL13+($G13*365)) | BP13: =IF(BQ13="","",_xlfn.DAYS(BQ13,$Q$2)) | BQ13: =IF(BO13="","",BO13+($G13*365)) | BS13: =IF(BT13="","",_xlfn.DAYS(BT13,$Q$2)) | BT13: =IF(BR13="","",BR13+($G13*365)) | BV13: =IF(BW13="","",_xlfn.DAYS(BW13,$Q$2)) | BW13: =IF(BU13="","",BU13+($G13*365)) | BY13: =IF(BZ13="","",_xlfn.DAYS(BZ13,$Q$2)) | BZ13: =IF(BX13="","",BX13+($G13*365)) | CB13: =IF(CC13="","",_xlfn.DAYS(CC13,$Q$2)) | CC13: =IF(CA13="","",CA13+($G13*365)) | CE13: =IF(CF13="","",_xlfn.DAYS(CF13,$Q$2)) | CF13: =IF(CD13="","",CD13+($G13*365)) | CH13: =IF(CI13="","",_xlfn.DAYS(CI13,$Q$2)) | CI13: =IF(CG13="","",CG13+($G13*365)) | CK13: =IF(CL13="","",_xlfn.DAYS(CL13,$Q$2)) | CL13: =IF(CJ13="","",CJ13+($G13*365)) | CN13: =IF(CO13="","",_xlfn.DAYS(CO13,$Q$2)) | CO13: =IF(CM13="","",CM13+($G13*365)) | CQ13: =IF(CR13="","",_xlfn.DAYS(CR13,$Q$2)) | CR13: =IF(CP13="","",CP13+($G13*365)) | CT13: =IF(CU13="","",_xlfn.DAYS(CU13,$Q$2)) | CU13: =IF(CS13="","",CS13+($G13*365)) | CW13: =IF(CX13="","",_xlfn.DAYS(CX13,$Q$2)) | CX13: =IF(CV13="","",CV13+($G13*365)) | CZ13: =IF(DA13="","",_xlfn.DAYS(DA13,$Q$2)) | DA13: =IF(CY13="","",CY13+($G13*365)) | DC13: =IF(DD13="","",_xlfn.DAYS(DD13,$Q$2)) | DD13: =IF(DB13="","",DB13+($G13*365)) | DF13: =IF(DG13="","",_xlfn.DAYS(DG13,$Q$2)) | DG13: =IF(DE13="","",DE13+($G13*365)) | DI13: =IF(DJ13="","",_xlfn.DAYS(DJ13,$Q$2)) | DJ13: =IF(DH13="","",DH13+($G13*365)) | DL13: =IF(DM13="","",_xlfn.DAYS(DM13,$Q$2)) | DM13: =IF(DK13="","",DK13+($G13*365)) | DO13: =IF(DP13="","",_xlfn.DAYS(DP13,$Q$2)) | DP13: =IF(DN13="","",DN13+($G13*365)) | DR13: =IF(DS13="","",_xlfn.DAYS(DS13,$Q$2)) | DS13: =IF(DQ13="","",DQ13+($G13*365)) | DU13: =IF(DV13="","",_xlfn.DAYS(DV13,$Q$2)) | DV13: =IF(DT13="","",DT13+($G13*365)) | DX13: =IF(DY13="","",_xlfn.DAYS(DY13,$Q$2)) | DY13: =IF(DW13="","",DW13+($G13*365)) | EA13: =IF(EB13="","",_xlfn.DAYS(EB13,$Q$2)) | EB13: =IF(DZ13="","",DZ13+($G13*365)) | ED13: =IF(EE13="","",_xlfn.DAYS(EE13,$Q$2)) | EE13: =IF(EC13="","",EC13+($G13*365)) | EG13: =IF(EH13="","",_xlfn.DAYS(EH13,$Q$2)) | EH13: =IF(EF13="","",EF13+($G13*365)) | EJ13: =IF(EK13="","",_xlfn.DAYS(EK13,$Q$2)) | EK13: =IF(EI13="","",EI13+($G13*365)) | EM13: =IF(EN13="","",_xlfn.DAYS(EN13,$Q$2)) | EN13: =IF(EL13="","",EL13+($G13*365)) | EP13: =IF(EQ13="","",_xlfn.DAYS(EQ13,$Q$2)) | EQ13: =IF(EO13="","",EO13+($G13*365)) | ES13: =IF(ET13="","",_xlfn.DAYS(ET13,$Q$2)) | ET13: =IF(ER13="","",ER13+($G13*365)) | EV13: =IF(EW13="","",_xlfn.DAYS(EW13,$Q$2)) | EW13: =IF(EU13="","",EU13+($G13*365)) | EY13: =IF(EZ13="","",_xlfn.DAYS(EZ13,$Q$2)) | EZ13: =IF(EX13="","",EX13+($G13*365)) | FB13: =IF(FC13="","",_xlfn.DAYS(FC13,$Q$2)) | FC13: =IF(FA13="","",FA13+($G13*365)) | FE13: =IF(FF13="","",_xlfn.DAYS(FF13,$Q$2)) | FF13: =IF(FD13="","",FD13+($G13*365)) | FH13: =IF(FI13="","",_xlfn.DAYS(FI13,$Q$2)) | FI13: =IF(FG13="","",FG13+($G13*365)) | FK13: =IF(FL13="","",_xlfn.DAYS(FL13,$Q$2)) | FL13: =IF(FJ13="","",FJ13+($G13*365)) | FN13: =IF(FO13="","",_xlfn.DAYS(FO13,$Q$2)) | FO13: =IF(FM13="","",FM13+($G13*365)) | FQ13: =IF(FR13="","",_xlfn.DAYS(FR13,$Q$2)) | FR13: =IF(FP13 = "", "",FP13+($G13*365)) | FT13: =IF(FU13="","",_xlfn.DAYS(FU13,$Q$2)) | FU13: =IF(FS13="","",FS13+($G13*365))
